Workbook

Sheet Top 100
A1: S.no | B1: Name | C1: SS | D1: FSR | E1: FQE | F1: FRU | G1: PU | H1: QP | I1: IPR | J1: FPPP | K1: GPH | L1: GUE | M1: MS | N1: GPHD | O1: RD | P1: WD | Q1: ESCS | R1: PCS | S1: PR
A2: 1 | B2: Indian Institute of Technology Madras | C2: 18.5 | D2: 30 | E2: 17.29 | F2: 30 | G2: 34.95 | H2: 34.37 | I2: 14 | J2: 9.78 | K2: 29.74 | L2: 15 | M2: 19.34 | N2: 16.98 | O2: 21.57 | P2: 14.88 | Q2: 9.4 | R2: 20 | S2: 100
A3: 2 | B3: Indian Institute of Technology Delhi | C3: 18.5 | D3: 23.18 | E3: 15.61 | F3: 28.41 | G3: 35 | H3: 37.63 | I3: 13 | J3: 6.56 | K3: 33.05 | L3: 13.06 | M3: 20.93 | N3: 17.49 | O3: 24.05 | P3: 14.07 | Q3: 7.27 | R3: 20 | S3: 98.53
A4: 3 | B4: Institute of Technology Bombay | C4: 18.5 | D4: 25.58 | E4: 16.91 | F4: 25.36 | G4: 31.61 | H4: 32.52 | I4: 13 | J4: 7.06 | K4: 32 | L4: 13.93 | M4: 19.99 | N4: 18.87 | O4: 19.25 | P4: 14.89 | Q4: 4.53 | R4: 20 | S4: 91.13
A5: 4 | B5: Indian Institute of Technology Kanpur | C5: 18.33 | D5: 28.72 | E5: 19.45 | F5: 27.76 | G5: 28.49 | H5: 28.87 | I5: 10 | J5: 6.72 | K5: 36.13 | L5: 15 | M5: 21.84 | N5: 16.08 | O5: 19.94 | P5: 12.94 | Q5: 7.74 | R5: 20 | S5: 84.19
A6: 5 | B6: Indian Institute of Technology Kharagpur | C6: 19.76 | D6: 21.5 | E6: 14.79 | F6: 22.47 | G6: 30.68 | H6: 34.86 | I6: 10 | J6: 3.75 | K6: 24.3 | L6: 13.99 | M6: 20.87 | N6: 20 | O6: 21.87 | P6: 11.93 | Q6: 4.02 | R6: 20 | S6: 80.26
A7: 6 | B7: Indian Institute of Technology Roorkee | C7: 17.66 | D7: 23.13 | E7: 15.28 | F7: 21.67 | G7: 30.25 | H7: 33.2 | I7: 7 | J7: 4.25 | K7: 37.74 | L7: 15 | M7: 20.17 | N7: 14.44 | O7: 23.72 | P7: 12.64 | Q7: 5.84 | R7: 20 | S7: 65.79
A8: 7 | B8: Indian Institute of Technology Guwahati | C8: 18.32 | D8: 24.57 | E8: 13.71 | F8: 20.22 | G8: 29.8 | H8: 29.68 | I8: 3 | J8: 5.58 | K8: 32.2 | L8: 14.94 | M8: 21.63 | N8: 15.71 | O8: 24.79 | P8: 11.94 | Q8: 2.84 | R8: 20 | S8: 55.38
A9: 8 | B9: Indian Institute of Technology Hyderabad | C9: 12.41 | D9: 30 | E9: 19.49 | F9: 26.83 | G9: 25.51 | H9: 23.82 | I9: 3 | J9: 5.18 | K9: 33.08 | L9: 15 | M9: 20.79 | N9: 9.01 | O9: 17.52 | P9: 12.57 | Q9: 5.6 | R9: 20 | S9: 65.31
A10: 9 | B10: National Institute of Technology Tiruchirapalli | C10: 17.5 | D10: 19.31 | E10: 13.02 | F10: 19.87 | G10: 25.31 | H10: 25.66 | I10: 6 | J10: 2.19 | K10: 35 | L10: 15 | M10: 17.34 | N10: 11.35 | O10: 16.71 | P10: 18.19 | Q10: 8.22 | R10: 20 | S10: 68.07
A11: 10 | B11: Institute of Technology (Banaras Hindu University) Varanasi | C11: 16.28 | D11: 18.79 | E11: 13.13 | F11: 18.06 | G11: 24.33 | H11: 27.64 | I11: 6 | J11: 2.49 | K11: 36.48 | L11: 14.98 | M11: 20.43 | N11: 12.9 | O11: 17.96 | P11: 10.7 | Q11: 9.23 | R11: 20 | S11: 60.05
A12: 11 | B12: Vellore Institute of Technology | C12: 20 | D12: 22.18 | E12: 13.86 | F12: 9.49 | G12: 27.5 | H12: 37.24 | I12: 7 | J12: 0.2 | K12: 28.72 | L12: 15 | M12: 13.37 | N12: 12.31 | O12: 19.47 | P12: 22.7 | Q12: 0.11 | R12: 20 | S12: 49.28
A13: 12 | B13: Jadavpur University | C13: 18.5 | D13: 27.77 | E13: 17.37 | F13: 14.6 | G13: 27.28 | H13: 27.04 | I13: 2.5 | J13: 2.66 | K13: 33.89 | L13: 15 | M13: 15.2 | N13: 12.46 | O13: 5.07 | P13: 18.53 | Q13: 5.29 | R13: 20 | S13: 41.13
... A101: 100 | B101: Siddaganga Institute of Technology | C101: 12.42 | D101: 30 | E101: 14.78 | F101: 9.49 | G101: 6.31 | H101: 8.09 | I101: 0.5 | J101: 4.1 | K101: 33.23 | L101: 14.95 | M101: 12.36 | N101: 1.23 | O101: 6.06 | P101: 28.02 | Q101: 5.73 | R101: 20 | S101: 10.06

Sheet IIT
A1: S. no | B1: IIT | C1: SS | D1: FSR | E1: FQE | F1: FRU | G1: PU | H1: QP | I1: IPR | J1: FPPP | K1: GPH | L1: GUE | M1: MS | N1: GPHD | O1: RD | P1: WD | Q1: ESCS | R1: PCS | S1: PR
A2: 1 | B2: Indian Institute of Technology Madras | C2: =VLOOKUP(B2, 'Top 100'!B:S, COLUMN()-1, FALSE) -> 18.5 | D2: =VLOOKUP(B2, 'Top 100'!B:S, COLUMN()-1, FALSE) -> 30 | E2: =VLOOKUP(B2, 'Top 100'!B:S, COLUMN()-1, FALSE) -> 17.29 | F2: =VLOOKUP(B2, 'Top 100'!B:S, COLUMN()-1, FALSE) -> 30 | G2: =VLOOKUP(B2, 'Top 100'!B:S, COLUMN()-1, FALSE) -> 34.95 | H2: =VLOOKUP(B2, 'Top 100'!B:S, COLUMN()-1, FALSE) -> 34.37 | I2: =VLOOKUP(B2, 'Top 100'!B:S, COLUMN()-1, FALSE) -> 14 | J2: =VLOOKUP(B2, 'Top 100'!B:S, COLUMN()-1, FALSE) -> 9.78 | K2: =VLOOKUP(B2, 'Top 100'!B:S, COLUMN()-1, FALSE) -> 29.74 | L2: =VLOOKUP(B2, 'Top 100'!B:S, COLUMN()-1, FALSE) -> 15 | M2: =VLOOKUP(B2, 'Top 100'!B:S, COLUMN()-1, FALSE) -> 19.34 | N2: =VLOOKUP(B2, 'Top 100'!B:S, COLUMN()-1, FALSE) -> 16.98 | O2: =VLOOKUP(B2, 'Top 100'!B:S, COLUMN()-1, FALSE) -> 21.57 | P2: =VLOOKUP(B2, 'Top 100'!B:S, COLUMN()-1, FALSE) -> 14.88 | Q2: =VLOOKUP(B2, 'Top 100'!B:S, COLUMN()-1, FALSE) -> 9.4 | R2: =VLOOKUP(B2, 'Top 100'!B:S, COLUMN()-1, FALSE) -> 20 | S2: =VLOOKUP(B2, 'Top 100'!B:S, COLUMN()-1, FALSE) -> 100
A3: 2 | B3: Indian Institute of Technology Delhi | C3: =VLOOKUP(B3, 'Top 100'!B:S, COLUMN()-1, FALSE) -> 18.5 | D3: =VLOOKUP(B3, 'Top 100'!B:S, COLUMN()-1, FALSE) -> 23.18 | E3: =VLOOKUP(B3, 'Top 100'!B:S, COLUMN()-1, FALSE) -> 15.61 | F3: =VLOOKUP(B3, 'Top 100'!B:S, COLUMN()-1, FALSE) -> 28.41 | G3: =VLOOKUP(B3, 'Top 100'!B:S, COLUMN()-1, FALSE) -> 35 | H3: =VLOOKUP(B3, 'Top 100'!B:S, COLUMN()-1, FALSE) -> 37.63 | I3: =VLOOKUP(B3, 'Top 100'!B:S, COLUMN()-1, FALSE) -> 13 | J3: =VLOOKUP(B3, 'Top 100'!B:S, COLUMN()-1, FALSE) -> 6.56 | K3: =VLOOKUP(B3, 'Top 100'!B:S, COLUMN()-1, FALSE) -> 33.05 | L3: =VLOOKUP(B3, 'Top 100'!B:S, COLUMN()-1, FALSE) -> 13.06 | M3: =VLOOKUP(B3, 'Top 100'!B:S, COLUMN()-1, FALSE) -> 20.93 | N3: =VLOOKUP(B3, 'Top 100'!B:S, COLUMN()-1, FALSE) -> 17.49 | O3: =VLOOKUP(B3, 'Top 100'!B:S, COLUMN()-1, FALSE) -> 24.05 | P3: =VLOOKUP(B3, 'Top 100'!B:S, COLUMN()-1, FALSE) -> 14.07 | Q3: =VLOOKUP(B3, 'Top 100'!B:S, COLUMN()-1, FALSE) -> 7.27 | R3: =VLOOKUP(B3, 'Top 100'!B:S, COLUMN()-1, FALSE) -> 20 | S3: =VLOOKUP(B3, 'Top 100'!B:S, COLUMN()-1, FALSE) -> 98.53
A4: 3 | B4: Indian Institute of Technology Bombay | C4: 18.5 | D4: 25.58 | E4: 16.91 | F4: 25.36 | G4: 31.61 | H4: 32.52 | I4: 13 | J4: 7.06 | K4: 32 | L4: 13.93 | M4: 19.99 | N4: 18.87 | O4: 19.25 | P4: 14.89 | Q4: 4.53 | R4: 20 | S4: 91.13
A5: 4 | B5: Indian Institute of Technology Kanpur | C5: =VLOOKUP(B5, 'Top 100'!B:S, COLUMN()-1, FALSE) -> 18.33 | D5: =VLOOKUP(B5, 'Top 100'!B:S, COLUMN()-1, FALSE) -> 28.72 | E5: =VLOOKUP(B5, 'Top 100'!B:S, COLUMN()-1, FALSE) -> 19.45 | F5: =VLOOKUP(B5, 'Top 100'!B:S, COLUMN()-1, FALSE) -> 27.76 | G5: =VLOOKUP(B5, 'Top 100'!B:S, COLUMN()-1, FALSE) -> 28.49 | H5: =VLOOKUP(B5, 'Top 100'!B:S, COLUMN()-1, FALSE) -> 28.87 | I5: =VLOOKUP(B5, 'Top 100'!B:S, COLUMN()-1, FALSE) -> 10 | J5: =VLOOKUP(B5, 'Top 100'!B:S, COLUMN()-1, FALSE) -> 6.72 | K5: =VLOOKUP(B5, 'Top 100'!B:S, COLUMN()-1, FALSE) -> 36.13 | L5: =VLOOKUP(B5, 'Top 100'!B:S, COLUMN()-1, FALSE) -> 15 | M5: =VLOOKUP(B5, 'Top 100'!B:S, COLUMN()-1, FALSE) -> 21.84 | N5: =VLOOKUP(B5, 'Top 100'!B:S, COLUMN()-1, FALSE) -> 16.08 | O5: =VLOOKUP(B5, 'Top 100'!B:S, COLUMN()-1, FALSE) -> 19.94 | P5: =VLOOKUP(B5, 'Top 100'!B:S, COLUMN()-1, FALSE) -> 12.94 | Q5: =VLOOKUP(B5, 'Top 100'!B:S, COLUMN()-1, FALSE) -> 7.74 | R5: =VLOOKUP(B5, 'Top 100'!B:S, COLUMN()-1, FALSE) -> 20 | S5: =VLOOKUP(B5, 'Top 100'!B:S, COLUMN()-1, FALSE) -> 84.19
A6: 5 | B6: Indian Institute of Technology Kharagpur | C6: =VLOOKUP(B6, 'Top 100'!B:S, COLUMN()-1, FALSE) -> 19.76 | D6: =VLOOKUP(B6, 'Top 100'!B:S, COLUMN()-1, FALSE) -> 21.5 | E6: =VLOOKUP(B6, 'Top 100'!B:S, COLUMN()-1, FALSE) -> 14.79 | F6: =VLOOKUP(B6, 'Top 100'!B:S, COLUMN()-1, FALSE) -> 22.47 | G6: =VLOOKUP(B6, 'Top 100'!B:S, COLUMN()-1, FALSE) -> 30.68 | H6: =VLOOKUP(B6, 'Top 100'!B:S, COLUMN()-1, FALSE) -> 34.86 | I6: =VLOOKUP(B6, 'Top 100'!B:S, COLUMN()-1, FALSE) -> 10 | J6: =VLOOKUP(B6, 'Top 100'!B:S, COLUMN()-1, FALSE) -> 3.75 | K6: =VLOOKUP(B6, 'Top 100'!B:S, COLUMN()-1, FALSE) -> 24.3 | L6: =VLOOKUP(B6, 'Top 100'!B:S, COLUMN()-1, FALSE) -> 13.99 | M6: =VLOOKUP(B6, 'Top 100'!B:S, COLUMN()-1, FALSE) -> 20.87 | N6: =VLOOKUP(B6, 'Top 100'!B:S, COLUMN()-1, FALSE) -> 20 | O6: =VLOOKUP(B6, 'Top 100'!B:S, COLUMN()-1, FALSE) -> 21.87 | P6: =VLOOKUP(B6, 'Top 100'!B:S, COLUMN()-1, FALSE) -> 11.93 | Q6: =VLOOKUP(B6, 'Top 100'!B:S, COLUMN()-1, FALSE) -> 4.02 | R6: =VLOOKUP(B6, 'Top 100'!B:S, COLUMN()-1, FALSE) -> 20 | S6: =VLOOKUP(B6, 'Top 100'!B:S, COLUMN()-1, FALSE) -> 80.26
A7: 6 | B7: Indian Institute of Technology Roorkee | C7: =VLOOKUP(B7, 'Top 100'!B:S, COLUMN()-1, FALSE) -> 17.66 | D7: =VLOOKUP(B7, 'Top 100'!B:S, COLUMN()-1, FALSE) -> 23.13 | E7: =VLOOKUP(B7, 'Top 100'!B:S, COLUMN()-1, FALSE) -> 15.28 | F7: =VLOOKUP(B7, 'Top 100'!B:S, COLUMN()-1, FALSE) -> 21.67 | G7: =VLOOKUP(B7, 'Top 100'!B:S, COLUMN()-1, FALSE) -> 30.25 | H7: =VLOOKUP(B7, 'Top 100'!B:S, COLUMN()-1, FALSE) -> 33.2 | I7: =VLOOKUP(B7, 'Top 100'!B:S, COLUMN()-1, FALSE) -> 7 | J7: =VLOOKUP(B7, 'Top 100'!B:S, COLUMN()-1, FALSE) -> 4.25 | K7: =VLOOKUP(B7, 'Top 100'!B:S, COLUMN()-1, FALSE) -> 37.74 | L7: =VLOOKUP(B7, 'Top 100'!B:S, COLUMN()-1, FALSE) -> 15 | M7: =VLOOKUP(B7, 'Top 100'!B:S, COLUMN()-1, FALSE) -> 20.17 | N7: =VLOOKUP(B7, 'Top 100'!B:S, COLUMN()-1, FALSE) -> 14.44 | O7: =VLOOKUP(B7, 'Top 100'!B:S, COLUMN()-1, FALSE) -> 23.72 | P7: =VLOOKUP(B7, 'Top 100'!B:S, COLUMN()-1, FALSE) -> 12.64 | Q7: =VLOOKUP(B7, 'Top 100'!B:S, COLUMN()-1, FALSE) -> 5.84 | R7: =VLOOKUP(B7, 'Top 100'!B:S, COLUMN()-1, FALSE) -> 20 | S7: =VLOOKUP(B7, 'Top 100'!B:S, COLUMN()-1, FALSE) -> 65.79
A8: 7 | B8: Indian Institute of Technology Guwahati | C8: =VLOOKUP(B8, 'Top 100'!B:S, COLUMN()-1, FALSE) -> 18.32 | D8: =VLOOKUP(B8, 'Top 100'!B:S, COLUMN()-1, FALSE) -> 24.57 | E8: =VLOOKUP(B8, 'Top 100'!B:S, COLUMN()-1, FALSE) -> 13.71 | F8: =VLOOKUP(B8, 'Top 100'!B:S, COLUMN()-1, FALSE) -> 20.22 | G8: =VLOOKUP(B8, 'Top 100'!B:S, COLUMN()-1, FALSE) -> 29.8 | H8: =VLOOKUP(B8, 'Top 100'!B:S, COLUMN()-1, FALSE) -> 29.68 | I8: =VLOOKUP(B8, 'Top 100'!B:S, COLUMN()-1, FALSE) -> 3 | J8: =VLOOKUP(B8, 'Top 100'!B:S, COLUMN()-1, FALSE) -> 5.58 | K8: =VLOOKUP(B8, 'Top 100'!B:S, COLUMN()-1, FALSE) -> 32.2 | L8: =VLOOKUP(B8, 'Top 100'!B:S, COLUMN()-1, FALSE) -> 14.94 | M8: =VLOOKUP(B8, 'Top 100'!B:S, COLUMN()-1, FALSE) -> 21.63 | N8: =VLOOKUP(B8, 'Top 100'!B:S, COLUMN()-1, FALSE) -> 15.71 | O8: =VLOOKUP(B8, 'Top 100'!B:S, COLUMN()-1, FALSE) -> 24.79 | P8: =VLOOKUP(B8, 'Top 100'!B:S, COLUMN()-1, FALSE) -> 11.94 | Q8: =VLOOKUP(B8, 'Top 100'!B:S, COLUMN()-1, FALSE) -> 2.84 | R8: =VLOOKUP(B8, 'Top 100'!B:S, COLUMN()-1, FALSE) -> 20 | S8: =VLOOKUP(B8, 'Top 100'!B:S, COLUMN()-1, FALSE) -> 55.38
A9: 8 | B9: Indian Institute of Technology Hyderabad | C9: =VLOOKUP(B9, 'Top 100'!B:S, COLUMN()-1, FALSE) -> 12.41 | D9: =VLOOKUP(B9, 'Top 100'!B:S, COLUMN()-1, FALSE) -> 30 | E9: =VLOOKUP(B9, 'Top 100'!B:S, COLUMN()-1, FALSE) -> 19.49 | F9: =VLOOKUP(B9, 'Top 100'!B:S, COLUMN()-1, FALSE) -> 26.83 | G9: =VLOOKUP(B9, 'Top 100'!B:S, COLUMN()-1, FALSE) -> 25.51 | H9: =VLOOKUP(B9, 'Top 100'!B:S, COLUMN()-1, FALSE) -> 23.82 | I9: =VLOOKUP(B9, 'Top 100'!B:S, COLUMN()-1, FALSE) -> 3 | J9: =VLOOKUP(B9, 'Top 100'!B:S, COLUMN()-1, FALSE) -> 5.18 | K9: =VLOOKUP(B9, 'Top 100'!B:S, COLUMN()-1, FALSE) -> 33.08 | L9: =VLOOKUP(B9, 'Top 100'!B:S, COLUMN()-1, FALSE) -> 15 | M9: =VLOOKUP(B9, 'Top 100'!B:S, COLUMN()-1, FALSE) -> 20.79 | N9: =VLOOKUP(B9, 'Top 100'!B:S, COLUMN()-1, FALSE) -> 9.01 | O9: =VLOOKUP(B9, 'Top 100'!B:S, COLUMN()-1, FALSE) -> 17.52 | P9: =VLOOKUP(B9, 'Top 100'!B:S, COLUMN()-1, FALSE) -> 12.57 | Q9: =VLOOKUP(B9, 'Top 100'!B:S, COLUMN()-1, FALSE) -> 5.6 | R9: =VLOOKUP(B9, 'Top 100'!B:S, COLUMN()-1, FALSE) -> 20 | S9: =VLOOKUP(B9, 'Top 100'!B:S, COLUMN()-1, FALSE) -> 65.31
A10: 9 | B10: Indian Institute of Technology (Indian School of Mines) Dhanbad | C10: =VLOOKUP(B10, 'Top 100'!B:S, COLUMN()-1, FALSE) -> 15.43 | D10: =VLOOKUP(B10, 'Top 100'!B:S, COLUMN()-1, FALSE) -> 23.35 | E10: =VLOOKUP(B10, 'Top 100'!B:S, COLUMN()-1, FALSE) -> 15.59 | F10: =VLOOKUP(B10, 'Top 100'!B:S, COLUMN()-1, FALSE) -> 19.02 | G10: =VLOOKUP(B10, 'Top 100'!B:S, COLUMN()-1, FALSE) -> 27.4 | H10: =VLOOKUP(B10, 'Top 100'!B:S, COLUMN()-1, FALSE) -> 29.33 | I10: =VLOOKUP(B10, 'Top 100'!B:S, COLUMN()-1, FALSE) -> 2.25 | J10: =VLOOKUP(B10, 'Top 100'!B:S, COLUMN()-1, FALSE) -> 1.93 | K10: =VLOOKUP(B10, 'Top 100'!B:S, COLUMN()-1, FALSE) -> 31.21 | L10: =VLOOKUP(B10, 'Top 100'!B:S, COLUMN()-1, FALSE) -> 12.69 | M10: =VLOOKUP(B10, 'Top 100'!B:S, COLUMN()-1, FALSE) -> 17.86 | N10: =VLOOKUP(B10, 'Top 100'!B:S, COLUMN()-1, FALSE) -> 14.18 | O10: =VLOOKUP(B10, 'Top 100'!B:S, COLUMN()-1, FALSE) -> 20.44 | P10: =VLOOKUP(B10, 'Top 100'!B:S, COLUMN()-1, FALSE) -> 11.62 | Q10: =VLOOKUP(B10, 'Top 100'!B:S, COLUMN()-1, FALSE) -> 77.18 | R10: =VLOOKUP(B10, 'Top 100'!B:S, COLUMN()-1, FALSE) -> 20 | S10: =VLOOKUP(B10, 'Top 100'!B:S, COLUMN()-1, FALSE) -> 33.72
A11: 10 | B11: Indian Institute of Technology Indore | C11: =VLOOKUP(B11, 'Top 100'!B:S, COLUMN()-1, FALSE) -> 10.73 | D11: =VLOOKUP(B11, 'Top 100'!B:S, COLUMN()-1, FALSE) -> 30 | E11: =VLOOKUP(B11, 'Top 100'!B:S, COLUMN()-1, FALSE) -> 18.01 | F11: =VLOOKUP(B11, 'Top 100'!B:S, COLUMN()-1, FALSE) -> 21.05 | G11: =VLOOKUP(B11, 'Top 100'!B:S, COLUMN()-1, FALSE) -> 24.71 | H11: =VLOOKUP(B11, 'Top 100'!B:S, COLUMN()-1, FALSE) -> 24.7 | I11: =VLOOKUP(B11, 'Top 100'!B:S, COLUMN()-1, FALSE) -> 2.25 | J11: =VLOOKUP(B11, 'Top 100'!B:S, COLUMN()-1, FALSE) -> 3.56 | K11: =VLOOKUP(B11, 'Top 100'!B:S, COLUMN()-1, FALSE) -> 30.64 | L11: =VLOOKUP(B11, 'Top 100'!B:S, COLUMN()-1, FALSE) -> 15 | M11: =VLOOKUP(B11, 'Top 100'!B:S, COLUMN()-1, FALSE) -> 20.22 | N11: =VLOOKUP(B11, 'Top 100'!B:S, COLUMN()-1, FALSE) -> 9.96 | O11: =VLOOKUP(B11, 'Top 100'!B:S, COLUMN()-1, FALSE) -> 20.09 | P11: =VLOOKUP(B11, 'Top 100'!B:S, COLUMN()-1, FALSE) -> 14.12 | Q11: =VLOOKUP(B11, 'Top 100'!B:S, COLUMN()-1, FALSE) -> 6.46 | R11: =VLOOKUP(B11, 'Top 100'!B:S, COLUMN()-1, FALSE) -> 20 | S11: =VLOOKUP(B11, 'Top 100'!B:S, COLUMN()-1, FALSE) -> 29.9
A12: 11 | B12: Indian Institute of Technology Gandhinagar | C12: =VLOOKUP(B12, 'Top 100'!B:S, COLUMN()-1, FALSE) -> 11.5 | D12: =VLOOKUP(B12, 'Top 100'!B:S, COLUMN()-1, FALSE) -> 30 | E12: =VLOOKUP(B12, 'Top 100'!B:S, COLUMN()-1, FALSE) -> 19.8 | F12: =VLOOKUP(B12, 'Top 100'!B:S, COLUMN()-1, FALSE) -> 27.09 | G12: =VLOOKUP(B12, 'Top 100'!B:S, COLUMN()-1, FALSE) -> 18.13 | H12: =VLOOKUP(B12, 'Top 100'!B:S, COLUMN()-1, FALSE) -> 16.38 | I12: =VLOOKUP(B12, 'Top 100'!B:S, COLUMN()-1, FALSE) -> 2 | J12: =VLOOKUP(B12, 'Top 100'!B:S, COLUMN()-1, FALSE) -> 5.69 | K12: =VLOOKUP(B12, 'Top 100'!B:S, COLUMN()-1, FALSE) -> 30.19 | L12: =VLOOKUP(B12, 'Top 100'!B:S, COLUMN()-1, FALSE) -> 15 | M12: =VLOOKUP(B12, 'Top 100'!B:S, COLUMN()-1, FALSE) -> 17.47 | N12: =VLOOKUP(B12, 'Top 100'!B:S, COLUMN()-1, FALSE) -> 7.66 | O12: =VLOOKUP(B12, 'Top 100'!B:S, COLUMN()-1, FALSE) -> 22.52 | P12: =VLOOKUP(B12, 'Top 100'!B:S, COLUMN()-1, FALSE) -> 18.53 | Q12: =VLOOKUP(B12, 'Top 100'!B:S, COLUMN()-1, FALSE) -> 4.52 | R12: =VLOOKUP(B12, 'Top 100'!B:S, COLUMN()-1, FALSE) -> 20 | S12: =VLOOKUP(B12, 'Top 100'!B:S, COLUMN()-1, FALSE) -> 36.08
A13: 12 | B13: Indian Institute of Technology Ropar | C13: =VLOOKUP(B13, 'Top 100'!B:S, COLUMN()-1, FALSE) -> 12.41 | D13: =VLOOKUP(B13, 'Top 100'!B:S, COLUMN()-1, FALSE) -> 26.58 | E13: =VLOOKUP(B13, 'Top 100'!B:S, COLUMN()-1, FALSE) -> 16.6 | F13: =VLOOKUP(B13, 'Top 100'!B:S, COLUMN()-1, FALSE) -> 21.72 | G13: =VLOOKUP(B13, 'Top 100'!B:S, COLUMN()-1, FALSE) -> 20.26 | H13: =VLOOKUP(B13, 'Top 100'!B:S, COLUMN()-1, FALSE) -> 19.53 | I13: =VLOOKUP(B13, 'Top 100'!B:S, COLUMN()-1, FALSE) -> 2.5 | J13: =VLOOKUP(B13, 'Top 100'!B:S, COLUMN()-1, FALSE) -> 4.11 | K13: =VLOOKUP(B13, 'Top 100'!B:S, COLUMN()-1, FALSE) -> 32.24 | L13: =VLOOKUP(B13, 'Top 100'!B:S, COLUMN()-1, FALSE) -> 15 | M13: =VLOOKUP(B13, 'Top 100'!B:S, COLUMN()-1, FALSE) -> 19.5 | N13: =VLOOKUP(B13, 'Top 100'!B:S, COLUMN()-1, FALSE) -> 6.85 | O13: =VLOOKUP(B13, 'Top 100'!B:S, COLUMN()-1, FALSE) -> 22.71 | P13: =VLOOKUP(B13, 'Top 100'!B:S, COLUMN()-1, FALSE) -> 14.33 | Q13: =VLOOKUP(B13, 'Top 100'!B:S, COLUMN()-1, FALSE) -> 8.1 | R13: =VLOOKUP(B13, 'Top 100'!B:S, COLUMN()-1, FALSE) -> 20 | S13: =VLOOKUP(B13, 'Top 100'!B:S, COLUMN()-1, FALSE) -> 32.06
A14: 13 | B14: Indian Institute of Technology Jodhpur | C14: =VLOOKUP(B14, 'Top 100'!B:S, COLUMN()-1, FALSE) -> 12.53 | D14: =VLOOKUP(B14, 'Top 100'!B:S, COLUMN()-1, FALSE) -> 30 | E14: =VLOOKUP(B14, 'Top 100'!B:S, COLUMN()-1, FALSE) -> 18.39 | F14: =VLOOKUP(B14, 'Top 100'!B:S, COLUMN()-1, FALSE) -> 26.13 | G14: =VLOOKUP(B14, 'Top 100'!B:S, COLUMN()-1, FALSE) -> 17.32 | H14: =VLOOKUP(B14, 'Top 100'!B:S, COLUMN()-1, FALSE) -> 17.75 | I14: =VLOOKUP(B14, 'Top 100'!B:S, COLUMN()-1, FALSE) -> 1 | J14: =VLOOKUP(B14, 'Top 100'!B:S, COLUMN()-1, FALSE) -> 4.17 | K14: =VLOOKUP(B14, 'Top 100'!B:S, COLUMN()-1, FALSE) -> 35.43 | L14: =VLOOKUP(B14, 'Top 100'!B:S, COLUMN()-1, FALSE) -> 15 | M14: =VLOOKUP(B14, 'Top 100'!B:S, COLUMN()-1, FALSE) -> 18.27 | N14: =VLOOKUP(B14, 'Top 100'!B:S, COLUMN()-1, FALSE) -> 3.56 | O14: =VLOOKUP(B14, 'Top 100'!B:S, COLUMN()-1, FALSE) -> 19.62 | P14: =VLOOKUP(B14, 'Top 100'!B:S, COLUMN()-1, FALSE) -> 20.45 | Q14: =VLOOKUP(B14, 'Top 100'!B:S, COLUMN()-1, FALSE) -> 6.17 | R14: =VLOOKUP(B14, 'Top 100'!B:S, COLUMN()-1, FALSE) -> 20 | S14: =VLOOKUP(B14, 'Top 100'!B:S, COLUMN()-1, FALSE) -> 13.5
A15: 14 | B15: Indian Institute of Technology Mandi | C15: =VLOOKUP(B15, 'Top 100'!B:S, COLUMN()-1, FALSE) -> 9.79 | D15: =VLOOKUP(B15, 'Top 100'!B:S, COLUMN()-1, FALSE) -> 26.28 | E15: =VLOOKUP(B15, 'Top 100'!B:S, COLUMN()-1, FALSE) -> 17.75 | F15: =VLOOKUP(B15, 'Top 100'!B:S, COLUMN()-1, FALSE) -> 21.07 | G15: =VLOOKUP(B15, 'Top 100'!B:S, COLUMN()-1, FALSE) -> 18.9 | H15: =VLOOKUP(B15, 'Top 100'!B:S, COLUMN()-1, FALSE) -> 18.29 | I15: =VLOOKUP(B15, 'Top 100'!B:S, COLUMN()-1, FALSE) -> 2.5 | J15: =VLOOKUP(B15, 'Top 100'!B:S, COLUMN()-1, FALSE) -> 2.11 | K15: =VLOOKUP(B15, 'Top 100'!B:S, COLUMN()-1, FALSE) -> 36.32 | L15: =VLOOKUP(B15, 'Top 100'!B:S, COLUMN()-1, FALSE) -> 13.5 | M15: =VLOOKUP(B15, 'Top 100'!B:S, COLUMN()-1, FALSE) -> 21.37 | N15: =VLOOKUP(B15, 'Top 100'!B:S, COLUMN()-1, FALSE) -> 7.85 | O15: =VLOOKUP(B15, 'Top 100'!B:S, COLUMN()-1, FALSE) -> 23.07 | P15: =VLOOKUP(B15, 'Top 100'!B:S, COLUMN()-1, FALSE) -> 19.08 | Q15: =VLOOKUP(B15, 'Top 100'!B:S, COLUMN()-1, FALSE) -> 8.36 | R15: =VLOOKUP(B15, 'Top 100'!B:S, COLUMN()-1, FALSE) -> 20 | S15: =VLOOKUP(B15, 'Top 100'!B:S, COLUMN()-1, FALSE) -> 19.9
A16: 15 | B16: Indian Institute of Technology Patna | C16: =VLOOKUP(B16, 'Top 100'!B:S, COLUMN()-1, FALSE) -> 12.02 | D16: =VLOOKUP(B16, 'Top 100'!B:S, COLUMN()-1, FALSE) -> 20.67 | E16: =VLOOKUP(B16, 'Top 100'!B:S, COLUMN()-1, FALSE) -> 13.68 | F16: =VLOOKUP(B16, 'Top 100'!B:S, COLUMN()-1, FALSE) -> 20.84 | G16: =VLOOKUP(B16, 'Top 100'!B:S, COLUMN()-1, FALSE) -> 22.18 | H16: =VLOOKUP(B16, 'Top 100'!B:S, COLUMN()-1, FALSE) -> 21.15 | I16: =VLOOKUP(B16, 'Top 100'!B:S, COLUMN()-1, FALSE) -> 2.25 | J16: =VLOOKUP(B16, 'Top 100'!B:S, COLUMN()-1, FALSE) -> 3.83 | K16: =VLOOKUP(B16, 'Top 100'!B:S, COLUMN()-1, FALSE) -> 33.92 | L16: =VLOOKUP(B16, 'Top 100'!B:S, COLUMN()-1, FALSE) -> 14.27 | M16: =VLOOKUP(B16, 'Top 100'!B:S, COLUMN()-1, FALSE) -> 20.74 | N16: =VLOOKUP(B16, 'Top 100'!B:S, COLUMN()-1, FALSE) -> 8.8 | O16: =VLOOKUP(B16, 'Top 100'!B:S, COLUMN()-1, FALSE) -> 18.31 | P16: =VLOOKUP(B16, 'Top 100'!B:S, COLUMN()-1, FALSE) -> 9.61 | Q16: =VLOOKUP(B16, 'Top 100'!B:S, COLUMN()-1, FALSE) -> 5.08 | R16: =VLOOKUP(B16, 'Top 100'!B:S, COLUMN()-1, FALSE) -> 20 | S16: =VLOOKUP(B16, 'Top 100'!B:S, COLUMN()-1, FALSE) -> 25.69
... A21: 20 | B21: Indian Institute of Technology Bhilai | C21: =VLOOKUP(B21, 'Top 100'!B:S, COLUMN()-1, FALSE) -> 6.36 | D21: =VLOOKUP(B21, 'Top 100'!B:S, COLUMN()-1, FALSE) -> 29.97 | E21: =VLOOKUP(B21, 'Top 100'!B:S, COLUMN()-1, FALSE) -> 17.45 | F21: =VLOOKUP(B21, 'Top 100'!B:S, COLUMN()-1, FALSE) -> 22.94 | G21: =VLOOKUP(B21, 'Top 100'!B:S, COLUMN()-1, FALSE) -> 6.65 | H21: =VLOOKUP(B21, 'Top 100'!B:S, COLUMN()-1, FALSE) -> 7.74 | I21: =VLOOKUP(B21, 'Top 100'!B:S, COLUMN()-1, FALSE) -> 0 | J21: =VLOOKUP(B21, 'Top 100'!B:S, COLUMN()-1, FALSE) -> 5.54 | K21: =VLOOKUP(B21, 'Top 100'!B:S, COLUMN()-1, FALSE) -> 32.6 | L21: =VLOOKUP(B21, 'Top 100'!B:S, COLUMN()-1, FALSE) -> 15 | M21: =VLOOKUP(B21, 'Top 100'!B:S, COLUMN()-1, FALSE) -> 17.43 | N21: =VLOOKUP(B21, 'Top 100'!B:S, COLUMN()-1, FALSE) -> 0.67 | O21: =VLOOKUP(B21, 'Top 100'!B:S, COLUMN()-1, FALSE) -> 22.56 | P21: =VLOOKUP(B21, 'Top 100'!B:S, COLUMN()-1, FALSE) -> 9.22 | Q21: =VLOOKUP(B21, 'Top 100'!B:S, COLUMN()-1, FALSE) -> 7.42 | R21: =VLOOKUP(B21, 'Top 100'!B:S, COLUMN()-1, FALSE) -> 20 | S21: =VLOOKUP(B21, 'Top 100'!B:S, COLUMN()-1, FALSE) -> 7.48

Sheet IIIT
A1: S. no | B1: IIIT | C1: SS | D1: FSR | E1: FQE | F1: FRU | G1: PU | H1: QP | I1: IPR | J1: FPPP | K1: GPH | L1: GUE | M1: MS | N1: GPHD | O1: RD | P1: WD | Q1: ESCS | R1: PCS | S1: PR
A2: 1 | B2: International Institute of Information Technology Hyderabad | C2: =VLOOKUP(B2, 'Top 100'!B:S, COLUMN()-1, FALSE) -> 9.33 | D2: =VLOOKUP(B2, 'Top 100'!B:S, COLUMN()-1, FALSE) -> 22.86 | E2: =VLOOKUP(B2, 'Top 100'!B:S, COLUMN()-1, FALSE) -> 15.64 | F2: =VLOOKUP(B2, 'Top 100'!B:S, COLUMN()-1, FALSE) -> 17.63 | G2: =VLOOKUP(B2, 'Top 100'!B:S, COLUMN()-1, FALSE) -> 18.7 | H2: =VLOOKUP(B2, 'Top 100'!B:S, COLUMN()-1, FALSE) -> 16.32 | I2: =VLOOKUP(B2, 'Top 100'!B:S, COLUMN()-1, FALSE) -> 1.5 | J2: =VLOOKUP(B2, 'Top 100'!B:S, COLUMN()-1, FALSE) -> 4.37 | K2: =VLOOKUP(B2, 'Top 100'!B:S, COLUMN()-1, FALSE) -> 27.16 | L2: =VLOOKUP(B2, 'Top 100'!B:S, COLUMN()-1, FALSE) -> 12.03 | M2: =VLOOKUP(B2, 'Top 100'!B:S, COLUMN()-1, FALSE) -> 25 | N2: =VLOOKUP(B2, 'Top 100'!B:S, COLUMN()-1, FALSE) -> 2.71 | O2: =VLOOKUP(B2, 'Top 100'!B:S, COLUMN()-1, FALSE) -> 20.96 | P2: =VLOOKUP(B2, 'Top 100'!B:S, COLUMN()-1, FALSE) -> 19.48 | Q2: =VLOOKUP(B2, 'Top 100'!B:S, COLUMN()-1, FALSE) -> 2.7 | R2: =VLOOKUP(B2, 'Top 100'!B:S, COLUMN()-1, FALSE) -> 20 | S2: =VLOOKUP(B2, 'Top 100'!B:S, COLUMN()-1, FALSE) -> 26.9
A3: 2 | B3: International Institute of Information Technology Bangalore | C3: =VLOOKUP(B3, 'Top 100'!B:S, COLUMN()-1, FALSE) -> 8.43 | D3: =VLOOKUP(B3, 'Top 100'!B:S, COLUMN()-1, FALSE) -> 19.13 | E3: =VLOOKUP(B3, 'Top 100'!B:S, COLUMN()-1, FALSE) -> 12.08 | F3: =VLOOKUP(B3, 'Top 100'!B:S, COLUMN()-1, FALSE) -> 26.85 | G3: =VLOOKUP(B3, 'Top 100'!B:S, COLUMN()-1, FALSE) -> 8.97 | H3: =VLOOKUP(B3, 'Top 100'!B:S, COLUMN()-1, FALSE) -> 5.67 | I3: =VLOOKUP(B3, 'Top 100'!B:S, COLUMN()-1, FALSE) -> 0.5 | J3: =VLOOKUP(B3, 'Top 100'!B:S, COLUMN()-1, FALSE) -> 7.77 | K3: =VLOOKUP(B3, 'Top 100'!B:S, COLUMN()-1, FALSE) -> 29.44 | L3: =VLOOKUP(B3, 'Top 100'!B:S, COLUMN()-1, FALSE) -> 15 | M3: =VLOOKUP(B3, 'Top 100'!B:S, COLUMN()-1, FALSE) -> 22.68 | N3: =VLOOKUP(B3, 'Top 100'!B:S, COLUMN()-1, FALSE) -> 1.3 | O3: =VLOOKUP(B3, 'Top 100'!B:S, COLUMN()-1, FALSE) -> 23.28 | P3: =VLOOKUP(B3, 'Top 100'!B:S, COLUMN()-1, FALSE) -> 15.65 | Q3: =VLOOKUP(B3, 'Top 100'!B:S, COLUMN()-1, FALSE) -> 0 | R3: =VLOOKUP(B3, 'Top 100'!B:S, COLUMN()-1, FALSE) -> 20 | S3: =VLOOKUP(B3, 'Top 100'!B:S, COLUMN()-1, FALSE) -> 22.1
A4: 3 | B4: Indraprastha Institute of Information Technology | C4: =VLOOKUP(B4, 'Top 100'!B:S, COLUMN()-1, FALSE) -> 11.7 | D4: =VLOOKUP(B4, 'Top 100'!B:S, COLUMN()-1, FALSE) -> 15.88 | E4: =VLOOKUP(B4, 'Top 100'!B:S, COLUMN()-1, FALSE) -> 11.03 | F4: =VLOOKUP(B4, 'Top 100'!B:S, COLUMN()-1, FALSE) -> 15.69 | G4: =VLOOKUP(B4, 'Top 100'!B:S, COLUMN()-1, FALSE) -> 14.81 | H4: =VLOOKUP(B4, 'Top 100'!B:S, COLUMN()-1, FALSE) -> 13.44 | I4: =VLOOKUP(B4, 'Top 100'!B:S, COLUMN()-1, FALSE) -> 0.25 | J4: =VLOOKUP(B4, 'Top 100'!B:S, COLUMN()-1, FALSE) -> 3.16 | K4: =VLOOKUP(B4, 'Top 100'!B:S, COLUMN()-1, FALSE) -> 33.03 | L4: =VLOOKUP(B4, 'Top 100'!B:S, COLUMN()-1, FALSE) -> 15 | M4: =VLOOKUP(B4, 'Top 100'!B:S, COLUMN()-1, FALSE) -> 19.67 | N4: =VLOOKUP(B4, 'Top 100'!B:S, COLUMN()-1, FALSE) -> 4.01 | O4: =VLOOKUP(B4, 'Top 100'!B:S, COLUMN()-1, FALSE) -> 11.68 | P4: =VLOOKUP(B4, 'Top 100'!B:S, COLUMN()-1, FALSE) -> 12.41 | Q4: =VLOOKUP(B4, 'Top 100'!B:S, COLUMN()-1, FALSE) -> 0.25 | R4: =VLOOKUP(B4, 'Top 100'!B:S, COLUMN()-1, FALSE) -> 20 | S4: =VLOOKUP(B4, 'Top 100'!B:S, COLUMN()-1, FALSE) -> 17.57
A5: 4 | B5: Indian Institute of Information Technology Allahabad | C5: =VLOOKUP(B5, 'Top 100'!B:S, COLUMN()-1, FALSE) -> 10.54 | D5: =VLOOKUP(B5, 'Top 100'!B:S, COLUMN()-1, FALSE) -> 14.68 | E5: =VLOOKUP(B5, 'Top 100'!B:S, COLUMN()-1, FALSE) -> 10.11 | F5: =VLOOKUP(B5, 'Top 100'!B:S, COLUMN()-1, FALSE) -> 11.64 | G5: =VLOOKUP(B5, 'Top 100'!B:S, COLUMN()-1, FALSE) -> 11.46 | H5: =VLOOKUP(B5, 'Top 100'!B:S, COLUMN()-1, FALSE) -> 11.67 | I5: =VLOOKUP(B5, 'Top 100'!B:S, COLUMN()-1, FALSE) -> 1 | J5: =VLOOKUP(B5, 'Top 100'!B:S, COLUMN()-1, FALSE) -> 0.81 | K5: =VLOOKUP(B5, 'Top 100'!B:S, COLUMN()-1, FALSE) -> 36.51 | L5: =VLOOKUP(B5, 'Top 100'!B:S, COLUMN()-1, FALSE) -> 15 | M5: =VLOOKUP(B5, 'Top 100'!B:S, COLUMN()-1, FALSE) -> 23.63 | N5: =VLOOKUP(B5, 'Top 100'!B:S, COLUMN()-1, FALSE) -> 5.47 | O5: =VLOOKUP(B5, 'Top 100'!B:S, COLUMN()-1, FALSE) -> 18.83 | P5: =VLOOKUP(B5, 'Top 100'!B:S, COLUMN()-1, FALSE) -> 12.18 | Q5: =VLOOKUP(B5, 'Top 100'!B:S, COLUMN()-1, FALSE) -> 3.41 | R5: =VLOOKUP(B5, 'Top 100'!B:S, COLUMN()-1, FALSE) -> 20 | S5: =VLOOKUP(B5, 'Top 100'!B:S, COLUMN()-1, FALSE) -> 27.14

Sheet NIT
A1: S. no | B1: NIT | C1: SS | D1: FSR | E1: FQE | F1: FRU | G1: PU | H1: QP | I1: IPR | J1: FPPP | K1: GPH | L1: GUE | M1: MS | N1: GPHD | O1: RD | P1: WD | Q1: ESCS | R1: PCS | S1: PR
A2: 1 | B2: National Institute of Technology Tiruchirappalli | C2: 17.5 | D2: 19.31 | E2: 13.02 | F2: 19.87 | G2: 25.31 | H2: 25.66 | I2: 6 | J2: 2.19 | K2: 35 | L2: 15 | M2: 17.34 | N2: 11.35 | O2: 16.71 | P2: 18.19 | Q2: 8.22 | R2: 20 | S2: 68.07
A3: 2 | B3: National Institute of Technology Karnataka, Surathkal | C3: =VLOOKUP(B3, 'Top 100'!B:S, COLUMN()-1, FALSE) -> 17.5 | D3: =VLOOKUP(B3, 'Top 100'!B:S, COLUMN()-1, FALSE) -> 20.02 | E3: =VLOOKUP(B3, 'Top 100'!B:S, COLUMN()-1, FALSE) -> 13 | F3: =VLOOKUP(B3, 'Top 100'!B:S, COLUMN()-1, FALSE) -> 24.14 | G3: =VLOOKUP(B3, 'Top 100'!B:S, COLUMN()-1, FALSE) -> 22.45 | H3: =VLOOKUP(B3, 'Top 100'!B:S, COLUMN()-1, FALSE) -> 21.45 | I3: =VLOOKUP(B3, 'Top 100'!B:S, COLUMN()-1, FALSE) -> 2.5 | J3: =VLOOKUP(B3, 'Top 100'!B:S, COLUMN()-1, FALSE) -> 2.93 | K3: =VLOOKUP(B3, 'Top 100'!B:S, COLUMN()-1, FALSE) -> 34.55 | L3: =VLOOKUP(B3, 'Top 100'!B:S, COLUMN()-1, FALSE) -> 15 | M3: =VLOOKUP(B3, 'Top 100'!B:S, COLUMN()-1, FALSE) -> 17.18 | N3: =VLOOKUP(B3, 'Top 100'!B:S, COLUMN()-1, FALSE) -> 11.7 | O3: =VLOOKUP(B3, 'Top 100'!B:S, COLUMN()-1, FALSE) -> 16.94 | P3: =VLOOKUP(B3, 'Top 100'!B:S, COLUMN()-1, FALSE) -> 16.02 | Q3: =VLOOKUP(B3, 'Top 100'!B:S, COLUMN()-1, FALSE) -> 9.34 | R3: =VLOOKUP(B3, 'Top 100'!B:S, COLUMN()-1, FALSE) -> 20 | S3: =VLOOKUP(B3, 'Top 100'!B:S, COLUMN()-1, FALSE) -> 52.37
A4: 3 | B4: National Institute of Technology Rourkela | C4: =VLOOKUP(B4, 'Top 100'!B:S, COLUMN()-1, FALSE) -> 17.5 | D4: =VLOOKUP(B4, 'Top 100'!B:S, COLUMN()-1, FALSE) -> 24.98 | E4: =VLOOKUP(B4, 'Top 100'!B:S, COLUMN()-1, FALSE) -> 16.27 | F4: =VLOOKUP(B4, 'Top 100'!B:S, COLUMN()-1, FALSE) -> 17.73 | G4: =VLOOKUP(B4, 'Top 100'!B:S, COLUMN()-1, FALSE) -> 26 | H4: =VLOOKUP(B4, 'Top 100'!B:S, COLUMN()-1, FALSE) -> 26.49 | I4: =VLOOKUP(B4, 'Top 100'!B:S, COLUMN()-1, FALSE) -> 2.5 | J4: =VLOOKUP(B4, 'Top 100'!B:S, COLUMN()-1, FALSE) -> 2.01 | K4: =VLOOKUP(B4, 'Top 100'!B:S, COLUMN()-1, FALSE) -> 31.45 | L4: =VLOOKUP(B4, 'Top 100'!B:S, COLUMN()-1, FALSE) -> 15 | M4: =VLOOKUP(B4, 'Top 100'!B:S, COLUMN()-1, FALSE) -> 15.17 | N4: =VLOOKUP(B4, 'Top 100'!B:S, COLUMN()-1, FALSE) -> 11.63 | O4: =VLOOKUP(B4, 'Top 100'!B:S, COLUMN()-1, FALSE) -> 15.69 | P4: =VLOOKUP(B4, 'Top 100'!B:S, COLUMN()-1, FALSE) -> 14.48 | Q4: =VLOOKUP(B4, 'Top 100'!B:S, COLUMN()-1, FALSE) -> 9.25 | R4: =VLOOKUP(B4, 'Top 100'!B:S, COLUMN()-1, FALSE) -> 20 | S4: =VLOOKUP(B4, 'Top 100'!B:S, COLUMN()-1, FALSE) -> 27.38
A5: 4 | B5: National Institute of Technology Warangal | C5: =VLOOKUP(B5, 'Top 100'!B:S, COLUMN()-1, FALSE) -> 16.5 | D5: =VLOOKUP(B5, 'Top 100'!B:S, COLUMN()-1, FALSE) -> 24.8 | E5: =VLOOKUP(B5, 'Top 100'!B:S, COLUMN()-1, FALSE) -> 16.34 | F5: =VLOOKUP(B5, 'Top 100'!B:S, COLUMN()-1, FALSE) -> 19.35 | G5: =VLOOKUP(B5, 'Top 100'!B:S, COLUMN()-1, FALSE) -> 22.36 | H5: =VLOOKUP(B5, 'Top 100'!B:S, COLUMN()-1, FALSE) -> 22.65 | I5: =VLOOKUP(B5, 'Top 100'!B:S, COLUMN()-1, FALSE) -> 2.25 | J5: =VLOOKUP(B5, 'Top 100'!B:S, COLUMN()-1, FALSE) -> 0.99 | K5: =VLOOKUP(B5, 'Top 100'!B:S, COLUMN()-1, FALSE) -> 32.93 | L5: =VLOOKUP(B5, 'Top 100'!B:S, COLUMN()-1, FALSE) -> 15 | M5: =VLOOKUP(B5, 'Top 100'!B:S, COLUMN()-1, FALSE) -> 17.84 | N5: =VLOOKUP(B5, 'Top 100'!B:S, COLUMN()-1, FALSE) -> 9.5 | O5: =VLOOKUP(B5, 'Top 100'!B:S, COLUMN()-1, FALSE) -> 14.57 | P5: =VLOOKUP(B5, 'Top 100'!B:S, COLUMN()-1, FALSE) -> 16.39 | Q5: =VLOOKUP(B5, 'Top 100'!B:S, COLUMN()-1, FALSE) -> 7.08 | R5: =VLOOKUP(B5, 'Top 100'!B:S, COLUMN()-1, FALSE) -> 20 | S5: =VLOOKUP(B5, 'Top 100'!B:S, COLUMN()-1, FALSE) -> 32.9
A6: 5 | B6: National Institute of Technology Silchar | C6: =VLOOKUP(B6, 'Top 100'!B:S, COLUMN()-1, FALSE) -> 14.35 | D6: =VLOOKUP(B6, 'Top 100'!B:S, COLUMN()-1, FALSE) -> 22.14 | E6: =VLOOKUP(B6, 'Top 100'!B:S, COLUMN()-1, FALSE) -> 14.98 | F6: =VLOOKUP(B6, 'Top 100'!B:S, COLUMN()-1, FALSE) -> 15.66 | G6: =VLOOKUP(B6, 'Top 100'!B:S, COLUMN()-1, FALSE) -> 24.45 | H6: =VLOOKUP(B6, 'Top 100'!B:S, COLUMN()-1, FALSE) -> 23.65 | I6: =VLOOKUP(B6, 'Top 100'!B:S, COLUMN()-1, FALSE) -> 4.5 | J6: =VLOOKUP(B6, 'Top 100'!B:S, COLUMN()-1, FALSE) -> 1.22 | K6: =VLOOKUP(B6, 'Top 100'!B:S, COLUMN()-1, FALSE) -> 33.97 | L6: =VLOOKUP(B6, 'Top 100'!B:S, COLUMN()-1, FALSE) -> 15 | M6: =VLOOKUP(B6, 'Top 100'!B:S, COLUMN()-1, FALSE) -> 15.91 | N6: =VLOOKUP(B6, 'Top 100'!B:S, COLUMN()-1, FALSE) -> 8.18 | O6: =VLOOKUP(B6, 'Top 100'!B:S, COLUMN()-1, FALSE) -> 13.18 | P6: =VLOOKUP(B6, 'Top 100'!B:S, COLUMN()-1, FALSE) -> 16.15 | Q6: =VLOOKUP(B6, 'Top 100'!B:S, COLUMN()-1, FALSE) -> 7.53 | R6: =VLOOKUP(B6, 'Top 100'!B:S, COLUMN()-1, FALSE) -> 20 | S6: =VLOOKUP(B6, 'Top 100'!B:S, COLUMN()-1, FALSE) -> 10.06
A7: 6 | B7: Visvesvaraya National Institute of Technology Nagpur | C7: =VLOOKUP(B7, 'Top 100'!B:S, COLUMN()-1, FALSE) -> 13.94 | D7: =VLOOKUP(B7, 'Top 100'!B:S, COLUMN()-1, FALSE) -> 26.24 | E7: =VLOOKUP(B7, 'Top 100'!B:S, COLUMN()-1, FALSE) -> 17.47 | F7: =VLOOKUP(B7, 'Top 100'!B:S, COLUMN()-1, FALSE) -> 17.07 | G7: =VLOOKUP(B7, 'Top 100'!B:S, COLUMN()-1, FALSE) -> 17.56 | H7: =VLOOKUP(B7, 'Top 100'!B:S, COLUMN()-1, FALSE) -> 16.91 | I7: =VLOOKUP(B7, 'Top 100'!B:S, COLUMN()-1, FALSE) -> 6.5 | J7: =VLOOKUP(B7, 'Top 100'!B:S, COLUMN()-1, FALSE) -> 2.39 | K7: =VLOOKUP(B7, 'Top 100'!B:S, COLUMN()-1, FALSE) -> 35.49 | L7: =VLOOKUP(B7, 'Top 100'!B:S, COLUMN()-1, FALSE) -> 15 | M7: =VLOOKUP(B7, 'Top 100'!B:S, COLUMN()-1, FALSE) -> 15.62 | N7: =VLOOKUP(B7, 'Top 100'!B:S, COLUMN()-1, FALSE) -> 7.79 | O7: =VLOOKUP(B7, 'Top 100'!B:S, COLUMN()-1, FALSE) -> 11.95 | P7: =VLOOKUP(B7, 'Top 100'!B:S, COLUMN()-1, FALSE) -> 20.22 | Q7: =VLOOKUP(B7, 'Top 100'!B:S, COLUMN()-1, FALSE) -> 3.45 | R7: =VLOOKUP(B7, 'Top 100'!B:S, COLUMN()-1, FALSE) -> 20 | S7: =VLOOKUP(B7, 'Top 100'!B:S, COLUMN()-1, FALSE) -> 21.28
A8: 7 | B8: Malaviya National Institute of Technology Jaipur | C8: 14.97 | D8: 23.94 | E8: 15.75 | F8: 14.59 | G8: 22.8 | H8: 22.92 | I8: 1.25 | J8: 1.7 | K8: 31.3 | L8: 15 | M8: 14.89 | N8: 8.23 | O8: 12.68 | P8: 19.53 | Q8: 73.55 | R8: 20 | S8: 11.2
A9: 8 | B9: National Institute of Technology Durgapur | C9: =VLOOKUP(B9, 'Top 100'!B:S, COLUMN()-1, FALSE) -> 14.09 | D9: =VLOOKUP(B9, 'Top 100'!B:S, COLUMN()-1, FALSE) -> 23.65 | E9: =VLOOKUP(B9, 'Top 100'!B:S, COLUMN()-1, FALSE) -> 16.12 | F9: =VLOOKUP(B9, 'Top 100'!B:S, COLUMN()-1, FALSE) -> 16.56 | G9: =VLOOKUP(B9, 'Top 100'!B:S, COLUMN()-1, FALSE) -> 18.45 | H9: =VLOOKUP(B9, 'Top 100'!B:S, COLUMN()-1, FALSE) -> 17.92 | I9: =VLOOKUP(B9, 'Top 100'!B:S, COLUMN()-1, FALSE) -> 0.75 | J9: =VLOOKUP(B9, 'Top 100'!B:S, COLUMN()-1, FALSE) -> 1.59 | K9: =VLOOKUP(B9, 'Top 100'!B:S, COLUMN()-1, FALSE) -> 38.71 | L9: =VLOOKUP(B9, 'Top 100'!B:S, COLUMN()-1, FALSE) -> 15 | M9: =VLOOKUP(B9, 'Top 100'!B:S, COLUMN()-1, FALSE) -> 14.89 | N9: =VLOOKUP(B9, 'Top 100'!B:S, COLUMN()-1, FALSE) -> 9.45 | O9: =VLOOKUP(B9, 'Top 100'!B:S, COLUMN()-1, FALSE) -> 14.74 | P9: =VLOOKUP(B9, 'Top 100'!B:S, COLUMN()-1, FALSE) -> 14.44 | Q9: =VLOOKUP(B9, 'Top 100'!B:S, COLUMN()-1, FALSE) -> 9.8 | R9: =VLOOKUP(B9, 'Top 100'!B:S, COLUMN()-1, FALSE) -> 20 | S9: =VLOOKUP(B9, 'Top 100'!B:S, COLUMN()-1, FALSE) -> 20.18
A10: 9 | B10: National Institute of Technology Delhi | C10: =VLOOKUP(B10, 'Top 100'!B:S, COLUMN()-1, FALSE) -> 7.96 | D10: =VLOOKUP(B10, 'Top 100'!B:S, COLUMN()-1, FALSE) -> 30 | E10: =VLOOKUP(B10, 'Top 100'!B:S, COLUMN()-1, FALSE) -> 19.59 | F10: =VLOOKUP(B10, 'Top 100'!B:S, COLUMN()-1, FALSE) -> 19.64 | G10: =VLOOKUP(B10, 'Top 100'!B:S, COLUMN()-1, FALSE) -> 14.91 | H10: =VLOOKUP(B10, 'Top 100'!B:S, COLUMN()-1, FALSE) -> 13.8 | I10: =VLOOKUP(B10, 'Top 100'!B:S, COLUMN()-1, FALSE) -> 0.5 | J10: =VLOOKUP(B10, 'Top 100'!B:S, COLUMN()-1, FALSE) -> 0.96 | K10: =VLOOKUP(B10, 'Top 100'!B:S, COLUMN()-1, FALSE) -> 32.6 | L10: =VLOOKUP(B10, 'Top 100'!B:S, COLUMN()-1, FALSE) -> 15 | M10: =VLOOKUP(B10, 'Top 100'!B:S, COLUMN()-1, FALSE) -> 17.27 | N10: =VLOOKUP(B10, 'Top 100'!B:S, COLUMN()-1, FALSE) -> 2.76 | O10: =VLOOKUP(B10, 'Top 100'!B:S, COLUMN()-1, FALSE) -> 20.57 | P10: =VLOOKUP(B10, 'Top 100'!B:S, COLUMN()-1, FALSE) -> 25.41 | Q10: =VLOOKUP(B10, 'Top 100'!B:S, COLUMN()-1, FALSE) -> 11.86 | R10: =VLOOKUP(B10, 'Top 100'!B:S, COLUMN()-1, FALSE) -> 20 | S10: =VLOOKUP(B10, 'Top 100'!B:S, COLUMN()-1, FALSE) -> 21.83
A11: 10 | B11: National Institute of Technology Patna | C11: =VLOOKUP(B11, 'Top 100'!B:S, COLUMN()-1, FALSE) -> 12.35 | D11: =VLOOKUP(B11, 'Top 100'!B:S, COLUMN()-1, FALSE) -> 20.29 | E11: =VLOOKUP(B11, 'Top 100'!B:S, COLUMN()-1, FALSE) -> 13.73 | F11: =VLOOKUP(B11, 'Top 100'!B:S, COLUMN()-1, FALSE) -> 14.54 | G11: =VLOOKUP(B11, 'Top 100'!B:S, COLUMN()-1, FALSE) -> 20.08 | H11: =VLOOKUP(B11, 'Top 100'!B:S, COLUMN()-1, FALSE) -> 21.08 | I11: =VLOOKUP(B11, 'Top 100'!B:S, COLUMN()-1, FALSE) -> 1.5 | J11: =VLOOKUP(B11, 'Top 100'!B:S, COLUMN()-1, FALSE) -> 1.21 | K11: =VLOOKUP(B11, 'Top 100'!B:S, COLUMN()-1, FALSE) -> 37.86 | L11: =VLOOKUP(B11, 'Top 100'!B:S, COLUMN()-1, FALSE) -> 15 | M11: =VLOOKUP(B11, 'Top 100'!B:S, COLUMN()-1, FALSE) -> 14.34 | N11: =VLOOKUP(B11, 'Top 100'!B:S, COLUMN()-1, FALSE) -> 6.95 | O11: =VLOOKUP(B11, 'Top 100'!B:S, COLUMN()-1, FALSE) -> 10.1 | P11: =VLOOKUP(B11, 'Top 100'!B:S, COLUMN()-1, FALSE) -> 11.45 | Q11: =VLOOKUP(B11, 'Top 100'!B:S, COLUMN()-1, FALSE) -> 8.25 | R11: =VLOOKUP(B11, 'Top 100'!B:S, COLUMN()-1, FALSE) -> 20 | S11: =VLOOKUP(B11, 'Top 100'!B:S, COLUMN()-1, FALSE) -> 10.42
A12: 11 | B12: Dr. B R Ambedkar National Institute of Technology Jalandhar | C12: =VLOOKUP(B12, 'Top 100'!B:S, COLUMN()-1, FALSE) -> 14.1 | D12: =VLOOKUP(B12, 'Top 100'!B:S, COLUMN()-1, FALSE) -> 27.63 | E12: =VLOOKUP(B12, 'Top 100'!B:S, COLUMN()-1, FALSE) -> 13.33 | F12: =VLOOKUP(B12, 'Top 100'!B:S, COLUMN()-1, FALSE) -> 12.1 | G12: =VLOOKUP(B12, 'Top 100'!B:S, COLUMN()-1, FALSE) -> 16.39 | H12: =VLOOKUP(B12, 'Top 100'!B:S, COLUMN()-1, FALSE) -> 18.7 | I12: =VLOOKUP(B12, 'Top 100'!B:S, COLUMN()-1, FALSE) -> 2 | J12: =VLOOKUP(B12, 'Top 100'!B:S, COLUMN()-1, FALSE) -> 0.27 | K12: =VLOOKUP(B12, 'Top 100'!B:S, COLUMN()-1, FALSE) -> 26.39 | L12: =VLOOKUP(B12, 'Top 100'!B:S, COLUMN()-1, FALSE) -> 13.52 | M12: =VLOOKUP(B12, 'Top 100'!B:S, COLUMN()-1, FALSE) -> 13.66 | N12: =VLOOKUP(B12, 'Top 100'!B:S, COLUMN()-1, FALSE) -> 6.57 | O12: =VLOOKUP(B12, 'Top 100'!B:S, COLUMN()-1, FALSE) -> 12.47 | P12: =VLOOKUP(B12, 'Top 100'!B:S, COLUMN()-1, FALSE) -> 20.37 | Q12: =VLOOKUP(B12, 'Top 100'!B:S, COLUMN()-1, FALSE) -> 7.37 | R12: =VLOOKUP(B12, 'Top 100'!B:S, COLUMN()-1, FALSE) -> 20 | S12: =VLOOKUP(B12, 'Top 100'!B:S, COLUMN()-1, FALSE) -> 16.97
A13: 12 | B13: Sardar Vallabhbhai National Institute of Technology | C13: =VLOOKUP(B13, 'Top 100'!B:S, COLUMN()-1, FALSE) -> 12.96 | D13: =VLOOKUP(B13, 'Top 100'!B:S, COLUMN()-1, FALSE) -> 21.27 | E13: =VLOOKUP(B13, 'Top 100'!B:S, COLUMN()-1, FALSE) -> 13.88 | F13: =VLOOKUP(B13, 'Top 100'!B:S, COLUMN()-1, FALSE) -> 14.91 | G13: =VLOOKUP(B13, 'Top 100'!B:S, COLUMN()-1, FALSE) -> 18.32 | H13: =VLOOKUP(B13, 'Top 100'!B:S, COLUMN()-1, FALSE) -> 18 | I13: =VLOOKUP(B13, 'Top 100'!B:S, COLUMN()-1, FALSE) -> 2.25 | J13: =VLOOKUP(B13, 'Top 100'!B:S, COLUMN()-1, FALSE) -> 1.05 | K13: =VLOOKUP(B13, 'Top 100'!B:S, COLUMN()-1, FALSE) -> 31.87 | L13: =VLOOKUP(B13, 'Top 100'!B:S, COLUMN()-1, FALSE) -> 14.6 | M13: =VLOOKUP(B13, 'Top 100'!B:S, COLUMN()-1, FALSE) -> 13.66 | N13: =VLOOKUP(B13, 'Top 100'!B:S, COLUMN()-1, FALSE) -> 6.88 | O13: =VLOOKUP(B13, 'Top 100'!B:S, COLUMN()-1, FALSE) -> 11.81 | P13: =VLOOKUP(B13, 'Top 100'!B:S, COLUMN()-1, FALSE) -> 18.64 | Q13: =VLOOKUP(B13, 'Top 100'!B:S, COLUMN()-1, FALSE) -> 4.43 | R13: =VLOOKUP(B13, 'Top 100'!B:S, COLUMN()-1, FALSE) -> 20 | S13: =VLOOKUP(B13, 'Top 100'!B:S, COLUMN()-1, FALSE) -> 13.5
A14: 13 | B14: Motilal Nehru National Institute of Technology | C14: =VLOOKUP(B14, 'Top 100'!B:S, COLUMN()-1, FALSE) -> 16.01 | D14: =VLOOKUP(B14, 'Top 100'!B:S, COLUMN()-1, FALSE) -> 15.21 | E14: =VLOOKUP(B14, 'Top 100'!B:S, COLUMN()-1, FALSE) -> 10.56 | F14: =VLOOKUP(B14, 'Top 100'!B:S, COLUMN()-1, FALSE) -> 16.74 | G14: =VLOOKUP(B14, 'Top 100'!B:S, COLUMN()-1, FALSE) -> 16.55 | H14: =VLOOKUP(B14, 'Top 100'!B:S, COLUMN()-1, FALSE) -> 17.13 | I14: =VLOOKUP(B14, 'Top 100'!B:S, COLUMN()-1, FALSE) -> 1.5 | J14: =VLOOKUP(B14, 'Top 100'!B:S, COLUMN()-1, FALSE) -> 1.4 | K14: =VLOOKUP(B14, 'Top 100'!B:S, COLUMN()-1, FALSE) -> 34.91 | L14: =VLOOKUP(B14, 'Top 100'!B:S, COLUMN()-1, FALSE) -> 15 | M14: =VLOOKUP(B14, 'Top 100'!B:S, COLUMN()-1, FALSE) -> 17.22 | N14: =VLOOKUP(B14, 'Top 100'!B:S, COLUMN()-1, FALSE) -> 7.94 | O14: =VLOOKUP(B14, 'Top 100'!B:S, COLUMN()-1, FALSE) -> 13.08 | P14: =VLOOKUP(B14, 'Top 100'!B:S, COLUMN()-1, FALSE) -> 11.45 | Q14: =VLOOKUP(B14, 'Top 100'!B:S, COLUMN()-1, FALSE) -> 8.41 | R14: =VLOOKUP(B14, 'Top 100'!B:S, COLUMN()-1, FALSE) -> 20 | S14: =VLOOKUP(B14, 'Top 100'!B:S, COLUMN()-1, FALSE) -> 18.17
A15: 14 | B15: National Institute of Technology Meghalaya | C15: =VLOOKUP(B15, 'Top 100'!B:S, COLUMN()-1, FALSE) -> 6.64 | D15: =VLOOKUP(B15, 'Top 100'!B:S, COLUMN()-1, FALSE) -> 29.59 | E15: =VLOOKUP(B15, 'Top 100'!B:S, COLUMN()-1, FALSE) -> 17.9 | F15: =VLOOKUP(B15, 'Top 100'!B:S, COLUMN()-1, FALSE) -> 17.79 | G15: =VLOOKUP(B15, 'Top 100'!B:S, COLUMN()-1, FALSE) -> 15.88 | H15: =VLOOKUP(B15, 'Top 100'!B:S, COLUMN()-1, FALSE) -> 13.56 | I15: =VLOOKUP(B15, 'Top 100'!B:S, COLUMN()-1, FALSE) -> 0.5 | J15: =VLOOKUP(B15, 'Top 100'!B:S, COLUMN()-1, FALSE) -> 2.45 | K15: =VLOOKUP(B15, 'Top 100'!B:S, COLUMN()-1, FALSE) -> 30.49 | L15: =VLOOKUP(B15, 'Top 100'!B:S, COLUMN()-1, FALSE) -> 12.9 | M15: =VLOOKUP(B15, 'Top 100'!B:S, COLUMN()-1, FALSE) -> 14.13 | N15: =VLOOKUP(B15, 'Top 100'!B:S, COLUMN()-1, FALSE) -> 3.36 | O15: =VLOOKUP(B15, 'Top 100'!B:S, COLUMN()-1, FALSE) -> 11.02 | P15: =VLOOKUP(B15, 'Top 100'!B:S, COLUMN()-1, FALSE) -> 18.73 | Q15: =VLOOKUP(B15, 'Top 100'!B:S, COLUMN()-1, FALSE) -> 11.14 | R15: =VLOOKUP(B15, 'Top 100'!B:S, COLUMN()-1, FALSE) -> 20 | S15: =VLOOKUP(B15, 'Top 100'!B:S, COLUMN()-1, FALSE) -> 3.49
A16: 15 | B16: National Institute of Technology Raipur | C16: =VLOOKUP(B16, 'Top 100'!B:S, COLUMN()-1, FALSE) -> 13.94 | D16: =VLOOKUP(B16, 'Top 100'!B:S, COLUMN()-1, FALSE) -> 19.01 | E16: =VLOOKUP(B16, 'Top 100'!B:S, COLUMN()-1, FALSE) -> 12.76 | F16: =VLOOKUP(B16, 'Top 100'!B:S, COLUMN()-1, FALSE) -> 12.12 | G16: =VLOOKUP(B16, 'Top 100'!B:S, COLUMN()-1, FALSE) -> 18.69 | H16: =VLOOKUP(B16, 'Top 100'!B:S, COLUMN()-1, FALSE) -> 19.36 | I16: =VLOOKUP(B16, 'Top 100'!B:S, COLUMN()-1, FALSE) -> 2.25 | J16: =VLOOKUP(B16, 'Top 100'!B:S, COLUMN()-1, FALSE) -> 0.5 | K16: =VLOOKUP(B16, 'Top 100'!B:S, COLUMN()-1, FALSE) -> 29.05 | L16: =VLOOKUP(B16, 'Top 100'!B:S, COLUMN()-1, FALSE) -> 15 | M16: =VLOOKUP(B16, 'Top 100'!B:S, COLUMN()-1, FALSE) -> 14.17 | N16: =VLOOKUP(B16, 'Top 100'!B:S, COLUMN()-1, FALSE) -> 7.76 | O16: =VLOOKUP(B16, 'Top 100'!B:S, COLUMN()-1, FALSE) -> 11.92 | P16: =VLOOKUP(B16, 'Top 100'!B:S, COLUMN()-1, FALSE) -> 16.48 | Q16: =VLOOKUP(B16, 'Top 100'!B:S, COLUMN()-1, FALSE) -> 8.56 | R16: =VLOOKUP(B16, 'Top 100'!B:S, COLUMN()-1, FALSE) -> 20 | S16: =VLOOKUP(B16, 'Top 100'!B:S, COLUMN()-1, FALSE) -> 3.91
A17: 16 | B17: Maulana Azad National Institute of Technology | C17: =VLOOKUP(B17, 'Top 100'!B:S, COLUMN()-1, FALSE) -> 15.01 | D17: =VLOOKUP(B17, 'Top 100'!B:S, COLUMN()-1, FALSE) -> 17.58 | E17: =VLOOKUP(B17, 'Top 100'!B:S, COLUMN()-1, FALSE) -> 12.32 | F17: =VLOOKUP(B17, 'Top 100'!B:S, COLUMN()-1, FALSE) -> 12.84 | G17: =VLOOKUP(B17, 'Top 100'!B:S, COLUMN()-1, FALSE) -> 14.61 | H17: =VLOOKUP(B17, 'Top 100'!B:S, COLUMN()-1, FALSE) -> 16.54 | I17: =VLOOKUP(B17, 'Top 100'!B:S, COLUMN()-1, FALSE) -> 2.25 | J17: =VLOOKUP(B17, 'Top 100'!B:S, COLUMN()-1, FALSE) -> 0.81 | K17: =VLOOKUP(B17, 'Top 100'!B:S, COLUMN()-1, FALSE) -> 33.93 | L17: =VLOOKUP(B17, 'Top 100'!B:S, COLUMN()-1, FALSE) -> 15 | M17: =VLOOKUP(B17, 'Top 100'!B:S, COLUMN()-1, FALSE) -> 16 | N17: =VLOOKUP(B17, 'Top 100'!B:S, COLUMN()-1, FALSE) -> 5.34 | O17: =VLOOKUP(B17, 'Top 100'!B:S, COLUMN()-1, FALSE) -> 12.28 | P17: =VLOOKUP(B17, 'Top 100'!B:S, COLUMN()-1, FALSE) -> 18.45 | Q17: =VLOOKUP(B17, 'Top 100'!B:S, COLUMN()-1, FALSE) -> 9.89 | R17: =VLOOKUP(B17, 'Top 100'!B:S, COLUMN()-1, FALSE) -> 20 | S17: =VLOOKUP(B17, 'Top 100'!B:S, COLUMN()-1, FALSE) -> 11.47
A18: 17 | B18: National Institute of Technology Srinagar | C18: =VLOOKUP(B18, 'Top 100'!B:S, COLUMN()-1, FALSE) -> 12.79 | D18: =VLOOKUP(B18, 'Top 100'!B:S, COLUMN()-1, FALSE) -> 19.55 | E18: =VLOOKUP(B18, 'Top 100'!B:S, COLUMN()-1, FALSE) -> 12.92 | F18: =VLOOKUP(B18, 'Top 100'!B:S, COLUMN()-1, FALSE) -> 17.34 | G18: =VLOOKUP(B18, 'Top 100'!B:S, COLUMN()-1, FALSE) -> 13.52 | H18: =VLOOKUP(B18, 'Top 100'!B:S, COLUMN()-1, FALSE) -> 14.35 | I18: =VLOOKUP(B18, 'Top 100'!B:S, COLUMN()-1, FALSE) -> 1.25 | J18: =VLOOKUP(B18, 'Top 100'!B:S, COLUMN()-1, FALSE) -> 1.07 | K18: =VLOOKUP(B18, 'Top 100'!B:S, COLUMN()-1, FALSE) -> 30.93 | L18: =VLOOKUP(B18, 'Top 100'!B:S, COLUMN()-1, FALSE) -> 15 | M18: =VLOOKUP(B18, 'Top 100'!B:S, COLUMN()-1, FALSE) -> 14.02 | N18: =VLOOKUP(B18, 'Top 100'!B:S, COLUMN()-1, FALSE) -> 7.22 | O18: =VLOOKUP(B18, 'Top 100'!B:S, COLUMN()-1, FALSE) -> 12.35 | P18: =VLOOKUP(B18, 'Top 100'!B:S, COLUMN()-1, FALSE) -> 15.62 | Q18: =VLOOKUP(B18, 'Top 100'!B:S, COLUMN()-1, FALSE) -> 10.64 | R18: =VLOOKUP(B18, 'Top 100'!B:S, COLUMN()-1, FALSE) -> 20 | S18: =VLOOKUP(B18, 'Top 100'!B:S, COLUMN()-1, FALSE) -> 6.33
A19: 18 | B19: National Institute of Technology Kurukshetra | C19: =VLOOKUP(B19, 'Top 100'!B:S, COLUMN()-1, FALSE) -> 14.63 | D19: =VLOOKUP(B19, 'Top 100'!B:S, COLUMN()-1, FALSE) -> 12.63 | E19: =VLOOKUP(B19, 'Top 100'!B:S, COLUMN()-1, FALSE) -> 7.85 | F19: =VLOOKUP(B19, 'Top 100'!B:S, COLUMN()-1, FALSE) -> 14.78 | G19: =VLOOKUP(B19, 'Top 100'!B:S, COLUMN()-1, FALSE) -> 15.72 | H19: =VLOOKUP(B19, 'Top 100'!B:S, COLUMN()-1, FALSE) -> 18.72 | I19: =VLOOKUP(B19, 'Top 100'!B:S, COLUMN()-1, FALSE) -> 2.5 | J19: =VLOOKUP(B19, 'Top 100'!B:S, COLUMN()-1, FALSE) -> 0.82 | K19: =VLOOKUP(B19, 'Top 100'!B:S, COLUMN()-1, FALSE) -> 30.43 | L19: =VLOOKUP(B19, 'Top 100'!B:S, COLUMN()-1, FALSE) -> 15 | M19: =VLOOKUP(B19, 'Top 100'!B:S, COLUMN()-1, FALSE) -> 15.55 | N19: =VLOOKUP(B19, 'Top 100'!B:S, COLUMN()-1, FALSE) -> 4.88 | O19: =VLOOKUP(B19, 'Top 100'!B:S, COLUMN()-1, FALSE) -> 13.94 | P19: =VLOOKUP(B19, 'Top 100'!B:S, COLUMN()-1, FALSE) -> 11.45 | Q19: =VLOOKUP(B19, 'Top 100'!B:S, COLUMN()-1, FALSE) -> 7.24 | R19: =VLOOKUP(B19, 'Top 100'!B:S, COLUMN()-1, FALSE) -> 20 | S19: =VLOOKUP(B19, 'Top 100'!B:S, COLUMN()-1, FALSE) -> 20.74
A20: 19 | B20: National Institute of Technology Agartala | C20: =VLOOKUP(B20, 'Top 100'!B:S, COLUMN()-1, FALSE) -> 12.59 | D20: =VLOOKUP(B20, 'Top 100'!B:S, COLUMN()-1, FALSE) -> 18.79 | E20: =VLOOKUP(B20, 'Top 100'!B:S, COLUMN()-1, FALSE) -> 12.22 | F20: =VLOOKUP(B20, 'Top 100'!B:S, COLUMN()-1, FALSE) -> 19.96 | G20: =VLOOKUP(B20, 'Top 100'!B:S, COLUMN()-1, FALSE) -> 11.34 | H20: =VLOOKUP(B20, 'Top 100'!B:S, COLUMN()-1, FALSE) -> 13.31 | I20: =VLOOKUP(B20, 'Top 100'!B:S, COLUMN()-1, FALSE) -> 0.75 | J20: =VLOOKUP(B20, 'Top 100'!B:S, COLUMN()-1, FALSE) -> 0.21 | K20: =VLOOKUP(B20, 'Top 100'!B:S, COLUMN()-1, FALSE) -> 33.25 | L20: =VLOOKUP(B20, 'Top 100'!B:S, COLUMN()-1, FALSE) -> 14.2 | M20: =VLOOKUP(B20, 'Top 100'!B:S, COLUMN()-1, FALSE) -> 12.71 | N20: =VLOOKUP(B20, 'Top 100'!B:S, COLUMN()-1, FALSE) -> 5.43 | O20: =VLOOKUP(B20, 'Top 100'!B:S, COLUMN()-1, FALSE) -> 12.06 | P20: =VLOOKUP(B20, 'Top 100'!B:S, COLUMN()-1, FALSE) -> 18.54 | Q20: =VLOOKUP(B20, 'Top 100'!B:S, COLUMN()-1, FALSE) -> 8.25 | R20: =VLOOKUP(B20, 'Top 100'!B:S, COLUMN()-1, FALSE) -> 20 | S20: =VLOOKUP(B20, 'Top 100'!B:S, COLUMN()-1, FALSE) -> 9.34
A21: 20 | B21: National Institute of Technology Puducherry | C21: =VLOOKUP(B21, 'Top 100'!B:S, COLUMN()-1, FALSE) -> 8.97 | D21: =VLOOKUP(B21, 'Top 100'!B:S, COLUMN()-1, FALSE) -> 22.95 | E21: =VLOOKUP(B21, 'Top 100'!B:S, COLUMN()-1, FALSE) -> 15.39 | F21: =VLOOKUP(B21, 'Top 100'!B:S, COLUMN()-1, FALSE) -> 14.47 | G21: =VLOOKUP(B21, 'Top 100'!B:S, COLUMN()-1, FALSE) -> 8.56 | H21: =VLOOKUP(B21, 'Top 100'!B:S, COLUMN()-1, FALSE) -> 10.83 | I21: =VLOOKUP(B21, 'Top 100'!B:S, COLUMN()-1, FALSE) -> 2 | J21: =VLOOKUP(B21, 'Top 100'!B:S, COLUMN()-1, FALSE) -> 0.59 | K21: =VLOOKUP(B21, 'Top 100'!B:S, COLUMN()-1, FALSE) -> 27.72 | L21: =VLOOKUP(B21, 'Top 100'!B:S, COLUMN()-1, FALSE) -> 15 | M21: =VLOOKUP(B21, 'Top 100'!B:S, COLUMN()-1, FALSE) -> 13.32 | N21: =VLOOKUP(B21, 'Top 100'!B:S, COLUMN()-1, FALSE) -> 2.42 | O21: =VLOOKUP(B21, 'Top 100'!B:S, COLUMN()-1, FALSE) -> 15.19 | P21: =VLOOKUP(B21, 'Top 100'!B:S, COLUMN()-1, FALSE) -> 19.65 | Q21: =VLOOKUP(B21, 'Top 100'!B:S, COLUMN()-1, FALSE) -> 11.75 | R21: =VLOOKUP(B21, 'Top 100'!B:S, COLUMN()-1, FALSE) -> 20 | S21: =VLOOKUP(B21, 'Top 100'!B:S, COLUMN()-1, FALSE) -> 9.7

Sheet Private University
A1: S. no | B1: Private University | C1: SS | D1: FSR | E1: FQE | F1: FRU | G1: PU | H1: QP | I1: IPR | J1: FPPP | K1: GPH | L1: GUE | M1: MS | N1: GPHD | O1: RD | P1: WD | Q1: ESCS | R1: PCS | S1: PR
A2: 1 | B2: Vellore Institute of Technology | C2: =VLOOKUP(B2, 'Top 100'!B:S, COLUMN()-1, FALSE) -> 20 | D2: =VLOOKUP(B2, 'Top 100'!B:S, COLUMN()-1, FALSE) -> 22.18 | E2: =VLOOKUP(B2, 'Top 100'!B:S, COLUMN()-1, FALSE) -> 13.86 | F2: =VLOOKUP(B2, 'Top 100'!B:S, COLUMN()-1, FALSE) -> 9.49 | G2: =VLOOKUP(B2, 'Top 100'!B:S, COLUMN()-1, FALSE) -> 27.5 | H2: =VLOOKUP(B2, 'Top 100'!B:S, COLUMN()-1, FALSE) -> 37.24 | I2: =VLOOKUP(B2, 'Top 100'!B:S, COLUMN()-1, FALSE) -> 7 | J2: =VLOOKUP(B2, 'Top 100'!B:S, COLUMN()-1, FALSE) -> 0.2 | K2: =VLOOKUP(B2, 'Top 100'!B:S, COLUMN()-1, FALSE) -> 28.72 | L2: =VLOOKUP(B2, 'Top 100'!B:S, COLUMN()-1, FALSE) -> 15 | M2: =VLOOKUP(B2, 'Top 100'!B:S, COLUMN()-1, FALSE) -> 13.37 | N2: =VLOOKUP(B2, 'Top 100'!B:S, COLUMN()-1, FALSE) -> 12.31 | O2: =VLOOKUP(B2, 'Top 100'!B:S, COLUMN()-1, FALSE) -> 19.47 | P2: =VLOOKUP(B2, 'Top 100'!B:S, COLUMN()-1, FALSE) -> 22.7 | Q2: =VLOOKUP(B2, 'Top 100'!B:S, COLUMN()-1, FALSE) -> 0.11 | R2: =VLOOKUP(B2, 'Top 100'!B:S, COLUMN()-1, FALSE) -> 20 | S2: =VLOOKUP(B2, 'Top 100'!B:S, COLUMN()-1, FALSE) -> 49.28
A3: 2 | B3: Amity University | C3: =VLOOKUP(B3, 'Top 100'!B:S, COLUMN()-1, FALSE) -> 16.47 | D3: =VLOOKUP(B3, 'Top 100'!B:S, COLUMN()-1, FALSE) -> 30 | E3: =VLOOKUP(B3, 'Top 100'!B:S, COLUMN()-1, FALSE) -> 15.91 | F3: =VLOOKUP(B3, 'Top 100'!B:S, COLUMN()-1, FALSE) -> 12.83 | G3: =VLOOKUP(B3, 'Top 100'!B:S, COLUMN()-1, FALSE) -> 25.59 | H3: =VLOOKUP(B3, 'Top 100'!B:S, COLUMN()-1, FALSE) -> 24.28 | I3: =VLOOKUP(B3, 'Top 100'!B:S, COLUMN()-1, FALSE) -> 9 | J3: =VLOOKUP(B3, 'Top 100'!B:S, COLUMN()-1, FALSE) -> 0.65 | K3: =VLOOKUP(B3, 'Top 100'!B:S, COLUMN()-1, FALSE) -> 30.1 | L3: =VLOOKUP(B3, 'Top 100'!B:S, COLUMN()-1, FALSE) -> 15 | M3: =VLOOKUP(B3, 'Top 100'!B:S, COLUMN()-1, FALSE) -> 9.95 | N3: =VLOOKUP(B3, 'Top 100'!B:S, COLUMN()-1, FALSE) -> 6.67 | O3: =VLOOKUP(B3, 'Top 100'!B:S, COLUMN()-1, FALSE) -> 18.04 | P3: =VLOOKUP(B3, 'Top 100'!B:S, COLUMN()-1, FALSE) -> 24.96 | Q3: =VLOOKUP(B3, 'Top 100'!B:S, COLUMN()-1, FALSE) -> 0.28 | R3: =VLOOKUP(B3, 'Top 100'!B:S, COLUMN()-1, FALSE) -> 20 | S3: =VLOOKUP(B3, 'Top 100'!B:S, COLUMN()-1, FALSE) -> 8.23
A4: 3 | B4: Chandigarh University | C4: =VLOOKUP(B4, 'Top 100'!B:S, COLUMN()-1, FALSE) -> 17.95 | D4: =VLOOKUP(B4, 'Top 100'!B:S, COLUMN()-1, FALSE) -> 30 | E4: =VLOOKUP(B4, 'Top 100'!B:S, COLUMN()-1, FALSE) -> 16.34 | F4: =VLOOKUP(B4, 'Top 100'!B:S, COLUMN()-1, FALSE) -> 11.92 | G4: =VLOOKUP(B4, 'Top 100'!B:S, COLUMN()-1, FALSE) -> 16.24 | H4: =VLOOKUP(B4, 'Top 100'!B:S, COLUMN()-1, FALSE) -> 20.19 | I4: =VLOOKUP(B4, 'Top 100'!B:S, COLUMN()-1, FALSE) -> 9 | J4: =VLOOKUP(B4, 'Top 100'!B:S, COLUMN()-1, FALSE) -> 0.32 | K4: =VLOOKUP(B4, 'Top 100'!B:S, COLUMN()-1, FALSE) -> 28.65 | L4: =VLOOKUP(B4, 'Top 100'!B:S, COLUMN()-1, FALSE) -> 15 | M4: =VLOOKUP(B4, 'Top 100'!B:S, COLUMN()-1, FALSE) -> 12.91 | N4: =VLOOKUP(B4, 'Top 100'!B:S, COLUMN()-1, FALSE) -> 9.65 | O4: =VLOOKUP(B4, 'Top 100'!B:S, COLUMN()-1, FALSE) -> 23.6 | P4: =VLOOKUP(B4, 'Top 100'!B:S, COLUMN()-1, FALSE) -> 30 | Q4: =VLOOKUP(B4, 'Top 100'!B:S, COLUMN()-1, FALSE) -> 1.95 | R4: =VLOOKUP(B4, 'Top 100'!B:S, COLUMN()-1, FALSE) -> 20 | S4: =VLOOKUP(B4, 'Top 100'!B:S, COLUMN()-1, FALSE) -> 24.19
A5: 4 | B5: Koneru Lakshmaiah Education Foundation University (K L College of Engineering) | C5: =VLOOKUP(B5, 'Top 100'!B:S, COLUMN()-1, FALSE) -> 17.47 | D5: =VLOOKUP(B5, 'Top 100'!B:S, COLUMN()-1, FALSE) -> 30 | E5: =VLOOKUP(B5, 'Top 100'!B:S, COLUMN()-1, FALSE) -> 17.63 | F5: =VLOOKUP(B5, 'Top 100'!B:S, COLUMN()-1, FALSE) -> 9.75 | G5: =VLOOKUP(B5, 'Top 100'!B:S, COLUMN()-1, FALSE) -> 20.77 | H5: =VLOOKUP(B5, 'Top 100'!B:S, COLUMN()-1, FALSE) -> 20.39 | I5: =VLOOKUP(B5, 'Top 100'!B:S, COLUMN()-1, FALSE) -> 6 | J5: =VLOOKUP(B5, 'Top 100'!B:S, COLUMN()-1, FALSE) -> 0.36 | K5: =VLOOKUP(B5, 'Top 100'!B:S, COLUMN()-1, FALSE) -> 28.63 | L5: =VLOOKUP(B5, 'Top 100'!B:S, COLUMN()-1, FALSE) -> 15 | M5: =VLOOKUP(B5, 'Top 100'!B:S, COLUMN()-1, FALSE) -> 12.06 | N5: =VLOOKUP(B5, 'Top 100'!B:S, COLUMN()-1, FALSE) -> 9.72 | O5: =VLOOKUP(B5, 'Top 100'!B:S, COLUMN()-1, FALSE) -> 15.28 | P5: =VLOOKUP(B5, 'Top 100'!B:S, COLUMN()-1, FALSE) -> 29.67 | Q5: =VLOOKUP(B5, 'Top 100'!B:S, COLUMN()-1, FALSE) -> 1.36 | R5: =VLOOKUP(B5, 'Top 100'!B:S, COLUMN()-1, FALSE) -> 20 | S5: =VLOOKUP(B5, 'Top 100'!B:S, COLUMN()-1, FALSE) -> 18.17
A6: 5 | B6: Kalasalingam Academy of Research and Education | C6: =VLOOKUP(B6, 'Top 100'!B:S, COLUMN()-1, FALSE) -> 16.48 | D6: =VLOOKUP(B6, 'Top 100'!B:S, COLUMN()-1, FALSE) -> 30 | E6: =VLOOKUP(B6, 'Top 100'!B:S, COLUMN()-1, FALSE) -> 18.58 | F6: =VLOOKUP(B6, 'Top 100'!B:S, COLUMN()-1, FALSE) -> 13.62 | G6: =VLOOKUP(B6, 'Top 100'!B:S, COLUMN()-1, FALSE) -> 15.35 | H6: =VLOOKUP(B6, 'Top 100'!B:S, COLUMN()-1, FALSE) -> 17.92 | I6: =VLOOKUP(B6, 'Top 100'!B:S, COLUMN()-1, FALSE) -> 5 | J6: =VLOOKUP(B6, 'Top 100'!B:S, COLUMN()-1, FALSE) -> 0.53 | K6: =VLOOKUP(B6, 'Top 100'!B:S, COLUMN()-1, FALSE) -> 36.27 | L6: =VLOOKUP(B6, 'Top 100'!B:S, COLUMN()-1, FALSE) -> 15 | M6: =VLOOKUP(B6, 'Top 100'!B:S, COLUMN()-1, FALSE) -> 11.07 | N6: =VLOOKUP(B6, 'Top 100'!B:S, COLUMN()-1, FALSE) -> 9.22 | O6: =VLOOKUP(B6, 'Top 100'!B:S, COLUMN()-1, FALSE) -> 19.04 | P6: =VLOOKUP(B6, 'Top 100'!B:S, COLUMN()-1, FALSE) -> 30 | Q6: =VLOOKUP(B6, 'Top 100'!B:S, COLUMN()-1, FALSE) -> 7.09 | R6: =VLOOKUP(B6, 'Top 100'!B:S, COLUMN()-1, FALSE) -> 20 | S6: =VLOOKUP(B6, 'Top 100'!B:S, COLUMN()-1, FALSE) -> 10.42
A7: 6 | B7: Kalinga Institute of Industrial Technology | C7: =VLOOKUP(B7, 'Top 100'!B:S, COLUMN()-1, FALSE) -> 20 | D7: =VLOOKUP(B7, 'Top 100'!B:S, COLUMN()-1, FALSE) -> 26.6 | E7: =VLOOKUP(B7, 'Top 100'!B:S, COLUMN()-1, FALSE) -> 16.79 | F7: =VLOOKUP(B7, 'Top 100'!B:S, COLUMN()-1, FALSE) -> 14.67 | G7: =VLOOKUP(B7, 'Top 100'!B:S, COLUMN()-1, FALSE) -> 15.88 | H7: =VLOOKUP(B7, 'Top 100'!B:S, COLUMN()-1, FALSE) -> 18.47 | I7: =VLOOKUP(B7, 'Top 100'!B:S, COLUMN()-1, FALSE) -> 8 | J7: =VLOOKUP(B7, 'Top 100'!B:S, COLUMN()-1, FALSE) -> 0.64 | K7: =VLOOKUP(B7, 'Top 100'!B:S, COLUMN()-1, FALSE) -> 23.59 | L7: =VLOOKUP(B7, 'Top 100'!B:S, COLUMN()-1, FALSE) -> 15 | M7: =VLOOKUP(B7, 'Top 100'!B:S, COLUMN()-1, FALSE) -> 11.63 | N7: =VLOOKUP(B7, 'Top 100'!B:S, COLUMN()-1, FALSE) -> 11.82 | O7: =VLOOKUP(B7, 'Top 100'!B:S, COLUMN()-1, FALSE) -> 26.01 | P7: =VLOOKUP(B7, 'Top 100'!B:S, COLUMN()-1, FALSE) -> 29.96 | Q7: =VLOOKUP(B7, 'Top 100'!B:S, COLUMN()-1, FALSE) -> 0.33 | R7: =VLOOKUP(B7, 'Top 100'!B:S, COLUMN()-1, FALSE) -> 20 | S7: =VLOOKUP(B7, 'Top 100'!B:S, COLUMN()-1, FALSE) -> 16.36
A8: 7 | B8: Shanmugha Arts Science Technology and Research Academy | C8: =VLOOKUP(B8, 'Top 100'!B:S, COLUMN()-1, FALSE) -> 16.32 | D8: =VLOOKUP(B8, 'Top 100'!B:S, COLUMN()-1, FALSE) -> 30 | E8: =VLOOKUP(B8, 'Top 100'!B:S, COLUMN()-1, FALSE) -> 17.95 | F8: =VLOOKUP(B8, 'Top 100'!B:S, COLUMN()-1, FALSE) -> 14.15 | G8: =VLOOKUP(B8, 'Top 100'!B:S, COLUMN()-1, FALSE) -> 15.47 | H8: =VLOOKUP(B8, 'Top 100'!B:S, COLUMN()-1, FALSE) -> 19.27 | I8: =VLOOKUP(B8, 'Top 100'!B:S, COLUMN()-1, FALSE) -> 2.25 | J8: =VLOOKUP(B8, 'Top 100'!B:S, COLUMN()-1, FALSE) -> 2.31 | K8: =VLOOKUP(B8, 'Top 100'!B:S, COLUMN()-1, FALSE) -> 34.86 | L8: =VLOOKUP(B8, 'Top 100'!B:S, COLUMN()-1, FALSE) -> 15 | M8: =VLOOKUP(B8, 'Top 100'!B:S, COLUMN()-1, FALSE) -> 12.57 | N8: =VLOOKUP(B8, 'Top 100'!B:S, COLUMN()-1, FALSE) -> 9.67 | O8: =VLOOKUP(B8, 'Top 100'!B:S, COLUMN()-1, FALSE) -> 14.25 | P8: =VLOOKUP(B8, 'Top 100'!B:S, COLUMN()-1, FALSE) -> 28.22 | Q8: =VLOOKUP(B8, 'Top 100'!B:S, COLUMN()-1, FALSE) -> 4.74 | R8: =VLOOKUP(B8, 'Top 100'!B:S, COLUMN()-1, FALSE) -> 20 | S8: =VLOOKUP(B8, 'Top 100'!B:S, COLUMN()-1, FALSE) -> 15.11
A9: 8 | B9: Saveetha Institute of Medical and Technical Sciences | C9: =VLOOKUP(B9, 'Top 100'!B:S, COLUMN()-1, FALSE) -> 13.18 | D9: =VLOOKUP(B9, 'Top 100'!B:S, COLUMN()-1, FALSE) -> 28.45 | E9: =VLOOKUP(B9, 'Top 100'!B:S, COLUMN()-1, FALSE) -> 19.47 | F9: =VLOOKUP(B9, 'Top 100'!B:S, COLUMN()-1, FALSE) -> 9.64 | G9: =VLOOKUP(B9, 'Top 100'!B:S, COLUMN()-1, FALSE) -> 27.22 | H9: =VLOOKUP(B9, 'Top 100'!B:S, COLUMN()-1, FALSE) -> 27.58 | I9: =VLOOKUP(B9, 'Top 100'!B:S, COLUMN()-1, FALSE) -> 5 | J9: =VLOOKUP(B9, 'Top 100'!B:S, COLUMN()-1, FALSE) -> 0.2 | K9: =VLOOKUP(B9, 'Top 100'!B:S, COLUMN()-1, FALSE) -> 10.58 | L9: =VLOOKUP(B9, 'Top 100'!B:S, COLUMN()-1, FALSE) -> 14.42 | M9: =VLOOKUP(B9, 'Top 100'!B:S, COLUMN()-1, FALSE) -> 8.61 | N9: =VLOOKUP(B9, 'Top 100'!B:S, COLUMN()-1, FALSE) -> 2.06 | O9: =VLOOKUP(B9, 'Top 100'!B:S, COLUMN()-1, FALSE) -> 15.86 | P9: =VLOOKUP(B9, 'Top 100'!B:S, COLUMN()-1, FALSE) -> 23.64 | Q9: =VLOOKUP(B9, 'Top 100'!B:S, COLUMN()-1, FALSE) -> 4.63 | R9: =VLOOKUP(B9, 'Top 100'!B:S, COLUMN()-1, FALSE) -> 20 | S9: =VLOOKUP(B9, 'Top 100'!B:S, COLUMN()-1, FALSE) -> 0.9
A10: 9 | B10: Manipal Institute of Technology | C10: =VLOOKUP(B10, 'Top 100'!B:S, COLUMN()-1, FALSE) -> 15.12 | D10: =VLOOKUP(B10, 'Top 100'!B:S, COLUMN()-1, FALSE) -> 27.16 | E10: =VLOOKUP(B10, 'Top 100'!B:S, COLUMN()-1, FALSE) -> 14.39 | F10: =VLOOKUP(B10, 'Top 100'!B:S, COLUMN()-1, FALSE) -> 10.92 | G10: =VLOOKUP(B10, 'Top 100'!B:S, COLUMN()-1, FALSE) -> 16.35 | H10: =VLOOKUP(B10, 'Top 100'!B:S, COLUMN()-1, FALSE) -> 19.98 | I10: =VLOOKUP(B10, 'Top 100'!B:S, COLUMN()-1, FALSE) -> 1 | J10: =VLOOKUP(B10, 'Top 100'!B:S, COLUMN()-1, FALSE) -> 0.12 | K10: =VLOOKUP(B10, 'Top 100'!B:S, COLUMN()-1, FALSE) -> 24.46 | L10: =VLOOKUP(B10, 'Top 100'!B:S, COLUMN()-1, FALSE) -> 15 | M10: =VLOOKUP(B10, 'Top 100'!B:S, COLUMN()-1, FALSE) -> 13.33 | N10: =VLOOKUP(B10, 'Top 100'!B:S, COLUMN()-1, FALSE) -> 4.79 | O10: =VLOOKUP(B10, 'Top 100'!B:S, COLUMN()-1, FALSE) -> 18.02 | P10: =VLOOKUP(B10, 'Top 100'!B:S, COLUMN()-1, FALSE) -> 21.07 | Q10: =VLOOKUP(B10, 'Top 100'!B:S, COLUMN()-1, FALSE) -> 1.14 | R10: =VLOOKUP(B10, 'Top 100'!B:S, COLUMN()-1, FALSE) -> 20 | S10: =VLOOKUP(B10, 'Top 100'!B:S, COLUMN()-1, FALSE) -> 30.56
A11: 10 | B11: Manipal University, Jaipur | C11: =VLOOKUP(B11, 'Top 100'!B:S, COLUMN()-1, FALSE) -> 14.67 | D11: =VLOOKUP(B11, 'Top 100'!B:S, COLUMN()-1, FALSE) -> 29.39 | E11: =VLOOKUP(B11, 'Top 100'!B:S, COLUMN()-1, FALSE) -> 16.48 | F11: =VLOOKUP(B11, 'Top 100'!B:S, COLUMN()-1, FALSE) -> 10.01 | G11: =VLOOKUP(B11, 'Top 100'!B:S, COLUMN()-1, FALSE) -> 14.79 | H11: =VLOOKUP(B11, 'Top 100'!B:S, COLUMN()-1, FALSE) -> 16.28 | I11: =VLOOKUP(B11, 'Top 100'!B:S, COLUMN()-1, FALSE) -> 6 | J11: =VLOOKUP(B11, 'Top 100'!B:S, COLUMN()-1, FALSE) -> 0.4 | K11: =VLOOKUP(B11, 'Top 100'!B:S, COLUMN()-1, FALSE) -> 25.03 | L11: =VLOOKUP(B11, 'Top 100'!B:S, COLUMN()-1, FALSE) -> 15 | M11: =VLOOKUP(B11, 'Top 100'!B:S, COLUMN()-1, FALSE) -> 11.24 | N11: =VLOOKUP(B11, 'Top 100'!B:S, COLUMN()-1, FALSE) -> 1.16 | O11: =VLOOKUP(B11, 'Top 100'!B:S, COLUMN()-1, FALSE) -> 22.52 | P11: =VLOOKUP(B11, 'Top 100'!B:S, COLUMN()-1, FALSE) -> 26.16 | Q11: =VLOOKUP(B11, 'Top 100'!B:S, COLUMN()-1, FALSE) -> 0.09 | R11: =VLOOKUP(B11, 'Top 100'!B:S, COLUMN()-1, FALSE) -> 20 | S11: =VLOOKUP(B11, 'Top 100'!B:S, COLUMN()-1, FALSE) -> 4.73
A12: 11 | B12: Graphic Era University | C12: =VLOOKUP(B12, 'Top 100'!B:S, COLUMN()-1, FALSE) -> 12.7 | D12: =VLOOKUP(B12, 'Top 100'!B:S, COLUMN()-1, FALSE) -> 26.11 | E12: =VLOOKUP(B12, 'Top 100'!B:S, COLUMN()-1, FALSE) -> 14.25 | F12: =VLOOKUP(B12, 'Top 100'!B:S, COLUMN()-1, FALSE) -> 13.33 | G12: =VLOOKUP(B12, 'Top 100'!B:S, COLUMN()-1, FALSE) -> 17.13 | H12: =VLOOKUP(B12, 'Top 100'!B:S, COLUMN()-1, FALSE) -> 17.69 | I12: =VLOOKUP(B12, 'Top 100'!B:S, COLUMN()-1, FALSE) -> 8 | J12: =VLOOKUP(B12, 'Top 100'!B:S, COLUMN()-1, FALSE) -> 0.59 | K12: =VLOOKUP(B12, 'Top 100'!B:S, COLUMN()-1, FALSE) -> 22.76 | L12: =VLOOKUP(B12, 'Top 100'!B:S, COLUMN()-1, FALSE) -> 14.59 | M12: =VLOOKUP(B12, 'Top 100'!B:S, COLUMN()-1, FALSE) -> 11.31 | N12: =VLOOKUP(B12, 'Top 100'!B:S, COLUMN()-1, FALSE) -> 3.09 | O12: =VLOOKUP(B12, 'Top 100'!B:S, COLUMN()-1, FALSE) -> 17.99 | P12: =VLOOKUP(B12, 'Top 100'!B:S, COLUMN()-1, FALSE) -> 27.14 | Q12: =VLOOKUP(B12, 'Top 100'!B:S, COLUMN()-1, FALSE) -> 4.4 | R12: =VLOOKUP(B12, 'Top 100'!B:S, COLUMN()-1, FALSE) -> 20 | S12: =VLOOKUP(B12, 'Top 100'!B:S, COLUMN()-1, FALSE) -> 30.99
A13: 12 | B13: Lovely Professional University | C13: =VLOOKUP(B13, 'Top 100'!B:S, COLUMN()-1, FALSE) -> 18 | D13: =VLOOKUP(B13, 'Top 100'!B:S, COLUMN()-1, FALSE) -> 21.78 | E13: =VLOOKUP(B13, 'Top 100'!B:S, COLUMN()-1, FALSE) -> 12.22 | F13: =VLOOKUP(B13, 'Top 100'!B:S, COLUMN()-1, FALSE) -> 7.41 | G13: =VLOOKUP(B13, 'Top 100'!B:S, COLUMN()-1, FALSE) -> 16.53 | H13: =VLOOKUP(B13, 'Top 100'!B:S, COLUMN()-1, FALSE) -> 23.41 | I13: =VLOOKUP(B13, 'Top 100'!B:S, COLUMN()-1, FALSE) -> 13 | J13: =VLOOKUP(B13, 'Top 100'!B:S, COLUMN()-1, FALSE) -> 0.08 | K13: =VLOOKUP(B13, 'Top 100'!B:S, COLUMN()-1, FALSE) -> 26.55 | L13: =VLOOKUP(B13, 'Top 100'!B:S, COLUMN()-1, FALSE) -> 15 | M13: =VLOOKUP(B13, 'Top 100'!B:S, COLUMN()-1, FALSE) -> 11.47 | N13: =VLOOKUP(B13, 'Top 100'!B:S, COLUMN()-1, FALSE) -> 4.75 | O13: =VLOOKUP(B13, 'Top 100'!B:S, COLUMN()-1, FALSE) -> 24.81 | P13: =VLOOKUP(B13, 'Top 100'!B:S, COLUMN()-1, FALSE) -> 19.39 | Q13: =VLOOKUP(B13, 'Top 100'!B:S, COLUMN()-1, FALSE) -> 2.9 | R13: =VLOOKUP(B13, 'Top 100'!B:S, COLUMN()-1, FALSE) -> 20 | S13: =VLOOKUP(B13, 'Top 100'!B:S, COLUMN()-1, FALSE) -> 21.83
A14: 13 | B14: SRM Institute of Science and Technology | C14: 18.04 | D14: 30 | E14: 16.92 | F14: 13.16 | G14: 27.61 | H14: 31.83 | I14: 9 | J14: 0.26 | K14: 30.37 | L14: 13.92 | M14: 10.03 | N14: 10.29 | O14: 20.88 | P14: 24.88 | Q14: 1.1 | R14: 20 | S14: 17.57
